Workbook

Sheet 真實IC
A1: Real
B2: Time | C2: 2013/12 | D2: 2014/01 | E2: 2014/02 | F2: 2014/03 | G2: 2014/04 | H2: 2014/05 | I2: 2014/06 | J2: 2014/07 | K2: 2014/08 | L2: 2014/09 | M2: 2014/10 | N2: 2014/11 | O2: 2014/12 | P2: 2015/01 | Q2: 2015/02 | R2: 2015/03 | S2: 2015/04 | T2: 2015/05 | U2: 2015/06 | V2: 2015/07 | W2: 2015/08 | X2: 2015/09 | Y2: 2015/10 | Z2: 2015/11 | AA2: 2015/12 | AB2: 2016/01 | AC2: 2016/02 | AD2: 2016/03 | AE2: 2016/04 | AF2: 2016/05 | AG2: 2016/06 | AH2: 2016/07 | AI2: 2016/08 | AJ2: 2016/09 | AK2: 2016/10 | AL2: 2016/11 | AM2: 2016/12 | AN2: 2017/01 | AO2: 2017/02 | AP2: 2017/03 | AQ2: 2017/04 | AR2: 2017/05 | AS2: 2017/06 | AT2: 2017/07 | AU2: 2017/08 | AV2: 2017/09 | AW2: 2017/10 | AX2: 2017/11 | AY2: 2017/12 | AZ2: 2018/01 | BA2: 2018/02 | BB2: 2018/03 | BC2: 2018/04 | BD2: 2018/05 | BE2: 2018/06 | BF2: 2018/07 | BG2: 2018/08 | BH2: 2018/09 | BI2: 2018/10 | BJ2: 2018/11 | BK2: 2018/12 | BL2: 2019/01 | BM2: 2019/02 | BN2: 2019/03 | BO2: 2019/04 | BP2: 2019/05 | BQ2: 2019/06 | BR2: 2019/07 | BS2: 2019/08 | BT2: 2019/09 | BU2: 2019/10 | BV2: 2019/11 | BW2: 2019/12 | BX2: 2020/01 | BY2: 2020/02 | BZ2: 2020/03 | CA2: 2020/04 | CB2: 2020/05 | CC2: 2020/06 | CD2: 2020/07 | CE2: 2020/08 | CF2: 2020/09 | CG2: 2020/10 | CH2: 2020/11 | CI2: 2020/12 | CJ2: 2021/01 | CK2: 2021/02 | CL2: 2021/03 | CM2: 2021/04 | CN2: 2021/05 | CO2: 2021/06 | CP2: 2021/07 | CQ2: 2021/08 | CR2: 2021/09 | CS2: 2021/10 | CT2: 2021/11 | CU2: 2021/12 | CV2: 2022/01 | CW2: 2022/02 | CX2: 2022/03 | CY2: 2022/04 | CZ2: 2022/05 | DA2: 2022/06 | DB2: 2022/07 | DC2: 2022/08 | DD2: 2022/09 | DE2: 2022/10 | DF2: 2022/11 | DG2: 2022/12 | DH2: 2023/01 | DI2: 2023/02 | DJ2: 2023/03 | DK2: 2023/04 | DL2: 2023/05 | DM2: 2023/06 | DN2: 2023/07 | DO2: 2023/08 | DP2: 2023/09 | DQ2: 2023/10 | DR2: 2023/11 | DS2: 2023/12 | DT2: 2024/01 | DU2: 2024/02 | DV2: 2024/03 | DW2: 2024/04 | DX2: 2024/05 | DY2: 2024/06 | DZ2: 2024/07 | EA2: 2024/08 | EB2: 2024/09 | EC2: 2024/10 | ED2: 2024/11 | EE2: 2024/12 | EF2: 2025/01 | EG2: 2025/02 | EH2: 2025/03 | EI2: 2025/04 | EJ2: 2025/05 | EK2: 2025/06 | EL2: 2025/07 | EM2: 2025/08
B3: bm | C3: 0.11254353 | D3: 0.034097093 | E3: -0.034092261 | F3: -0.016058652 | G3: -0.0032385096 | H3: 0.037901102 | I3: 0.19658042 | J3: 0.123748 | K3: -0.0034480581 | L3: 0.056295168 | M3: -0.033270601 | N3: 0.13532466 | O3: 0.02969531 | P3: -0.075919536 | Q3: -0.062747606 | R3: 0.034334773 | S3: -0.11448918 | T3: -0.128411 | U3: -0.01815403 | V3: 0.097284226 | W3: 0.06448606 | X3: 0.1327038 | Y3: -0.14506291 | Z3: 0.15983802 | AA3: -0.079439674 | AB3: 0.065463771 | AC3: 0.10841757 | AD3: 0.035162094 | AE3: -0.13259397 | AF3: 0.079167282 | AG3: 0.1474472 | AH3: 0.10818108 | AI3: 0.031505046 | AJ3: 0.068324574 | AK3: 0.13938042 | AL3: 0.0015927447 | AM3: 0.11699323 | AN3: 0.18348806 | AO3: -0.013624633 | AP3: -0.10636754 | AQ3: -0.026929215 | AR3: 0.042036531 | AS3: 0.018696587 | AT3: 0.050640506 | AU3: 0.060413159 | AV3: -0.049074617 | AW3: 0.041357509 | AX3: 0.1327231 | AY3: 0.05462578 | AZ3: 0.015696796 | BA3: 0.012690345 | BB3: 0.10435302 | BC3: 0.027796633 | BD3: 0.015784322 | BE3: 0.053739938 | BF3: 0.15375844 | BG3: 0.14726982 | BH3: 0.058771535 | BI3: 0.089685564 | BJ3: -0.041235808 | BK3: -0.085734728 | BL3: 0.06541404 | BM3: -0.031368353 | BN3: 0.035359622 | BO3: 0.077704285 | BP3: -0.014539108 | BQ3: 0.054478665 | BR3: -0.011979953 | BS3: 0.061686425 | BT3: 0.017609737 | BU3: 0.001762998 | BV3: 0.079901428 | BW3: -0.026106377 | BX3: 0.022152374 | BY3: -0.070677725 | BZ3: 0.10127162 | CA3: -0.11166328 | CB3: 0.021342222 | CC3: -0.0047361279 | CD3: 0.17955101 | CE3: 0.061307643 | CF3: 0.091604774 | CG3: 0.097692005 | CH3: 0.15714712 | CI3: -0.088647186 | CJ3: -0.014935576 | CK3: 0.038208336 | CL3: 0.31725854 | CM3: -0.04994997 | CN3: -0.038447027 | CO3: 0.00071081192 | CP3: 0.14471258 | CQ3: 0.14928899 | CR3: -0.039801054 | CS3: -0.046545919 | CT3: 0.034133664 | CU3: 0.12875406 | CV3: 0.031635368 | CW3: 0.041194563 | CX3: 0.16319544 | CY3: -0.043115028 | CZ3: 0.22006844 | DA3: -0.04142373 | DB3: -0.011737974 | DC3: 0.10777107 | DD3: 0.067224014 | DE3: -0.040137128 | DF3: 0.036396903 | DG3: -0.098061051 | DH3: -0.012045848 | DI3: -0.089410575 | DJ3: 0.054992879 | DK3: -0.057186589 | DL3: -0.029284301 | DM3: -0.031402929 | DN3: 0.084413623 | DO3: 0.048170818 | DP3: 0.090346423 | DQ3: -0.11867639 | DR3: 0.11050757 | DS3: -0.073814619 | DT3: -0.10633883 | DU3: 0.0096230219 | DV3: 0.14417122 | DW3: 0.085312212 | DX3: -0.11038018 | DY3: 0.12870772 | DZ3: -0.053270106 | EA3: 0.17325686 | EB3: 0.012264442 | EC3: 0.077320493 | ED3: -0.16510374 | EE3: 0.077592443 | EF3: 0.056688315 | EG3: 0.1757144 | EH3: -0.050736759 | EI3: -0.032979675 | EJ3: -0.1750733 | EK3: 0.075703333 | EL3: -0.11145874 | EM3: #NUM!
B4: size | C4: -0.26567505 | D4: -0.26274582 | E4: -0.078695496 | F4: 0.065706805 | G4: -0.059999729 | H4: -0.090782629 | I4: -0.029543457 | J4: 0.06875609 | K4: -0.045430805 | L4: 0.092349485 | M4: 0.0055332373 | N4: -0.20262956 | O4: -0.055439189 | P4: 0.063019438 | Q4: -0.051127471 | R4: -0.0026369264 | S4: 0.11737044 | T4: 0.028121058 | U4: 0.024399698 | V4: 0.0024693189 | W4: -0.12931199 | X4: -0.078183592 | Y4: -0.016789063 | Z4: -0.021755872 | AA4: 0.056064772 | AB4: -0.026152478 | AC4: -0.070545451 | AD4: -0.046059359 | AE4: 0.13302405 | AF4: -0.089277754 | AG4: -0.059320758 | AH4: -0.055248054 | AI4: -0.03443289 | AJ4: -0.0010118202 | AK4: 0.010080194 | AL4: -0.11988371 | AM4: -0.0052132143 | AN4: -0.10834391 | AO4: -0.058361176 | AP4: 0.010829655 | AQ4: 0.0091678033 | AR4: 0.094714182 | AS4: -0.024402385 | AT4: 0.0020132029 | AU4: -0.16715058 | AV4: 0.033972262 | AW4: -0.016836938 | AX4: -0.034706448 | AY4: 0.0051832253 | AZ4: -0.11973657 | BA4: -0.13521273 | BB4: 0.016982 | BC4: 0.023074368 | BD4: -0.11999454 | BE4: 0.12932848 | BF4: 0.016709915 | BG4: -0.022306747 | BH4: 0.039303081 | BI4: -0.10048888 | BJ4: -0.10199028 | BK4: 0.099875651 | BL4: -0.032934037 | BM4: 0.0262875 | BN4: 0.10734549 | BO4: -0.025606337 | BP4: 0.12241177 | BQ4: -0.045440179 | BR4: -0.071268977 | BS4: -0.068098859 | BT4: 0.092203282 | BU4: 0.082899618 | BV4: -0.041301127 | BW4: -0.099351182 | BX4: -0.038144887 | BY4: 0.11248742 | BZ4: -0.037880283 | CA4: -0.091542003 | CB4: -0.12463256 | CC4: -0.061699946 | CD4: -0.075868372 | CE4: -0.22128938 | CF4: 0.0086756078 | CG4: 0.031786264 | CH4: -0.037814116 | CI4: 0.049549068 | CJ4: -0.010429677 | CK4: -0.083344347 | CL4: -0.053422112 | CM4: 0.19037761 | CN4: 0.058217829 | CO4: -0.14266652 | CP4: 0.041776779 | CQ4: -0.16944775 | CR4: -0.084810245 | CS4: -0.03477087 | CT4: -0.11929695 | CU4: -0.017795179 | CV4: -0.014834128 | CW4: -0.046319066 | CX4: -0.09663469 | CY4: -0.078834385 | CZ4: -0.21252635 | DA4: -0.11368552 | DB4: -0.1831019 | DC4: -0.042499865 | DD4: 0.027817596 | DE4: 0.068607937 | DF4: -0.13309486 | DG4: 0.22249787 | DH4: -0.13075878 | DI4: -0.10969183 | DJ4: -0.11047372 | DK4: 0.085555392 | DL4: -0.037902764 | DM4: 0.083550635 | DN4: -0.055064654 | DO4: -0.091404376 | DP4: -0.14635791 | DQ4: 0.07258441 | DR4: -0.036982983 | DS4: -0.15848873 | DT4: -0.076734871 | DU4: 0.1465233 | DV4: 0.0092142529 | DW4: -0.12809453 | DX4: -0.057788778 | DY4: -0.10353071 | DZ4: -0.053247234 | EA4: -0.11101122 | EB4: -0.057337042 | EC4: 0.053167127 | ED4: 0.055871006 | EE4: 0.15335804 | EF4: -0.11423136 | EG4: -0.044005617 | EH4: 0.017544152 | EI4: 0.086430773 | EJ4: 0.13519055 | EK4: 0.12749822 | EL4: -0.030403121 | EM4: #NUM!
B5: mom | C5: -0.024114963 | D5: 0.1401006 | E5: -0.0054828677 | F5: -0.04806796 | G5: 0.098556491 | H5: 0.0040265399 | I5: -0.054392917 | J5: -0.00078467923 | K5: 0.03198565 | L5: -0.0052053083 | M5: 0.083785175 | N5: -0.056914478 | O5: 0.06851042 | P5: 0.028609346 | Q5: 0.066853829 | R5: -0.0022018586 | S5: 0.13430089 | T5: 0.13091808 | U5: 0.013133991 | V5: 0.026183164 | W5: -0.094297429 | X5: -0.30132339 | Y5: 0.10842895 | Z5: -0.14174493 | AA5: 0.11702124 | AB5: -0.022180044 | AC5: -0.086460961 | AD5: 0.021464874 | AE5: 0.15421824 | AF5: -0.14648945 | AG5: -0.047015552 | AH5: 0.019690199 | AI5: 0.039309116 | AJ5: -0.026623525 | AK5: -0.025125102 | AL5: -0.10344397 | AM5: 0.06190072 | AN5: 0.076731055 | AO5: 0.098982723 | AP5: 0.054076693 | AQ5: -0.030251892 | AR5: 0.00044910599 | AS5: 0.070194262 | AT5: 0.17429282 | AU5: -0.081385666 | AV5: 0.15075612 | AW5: 0.057401718 | AX5: -0.15692285 | AY5: 0.047095412 | AZ5: -0.057117988 | BA5: -0.022411435 | BB5: -0.15274623 | BC5: 0.022968193 | BD5: 0.0010412666 | BE5: -0.13310703 | BF5: -0.19610968 | BG5: -0.18881309 | BH5: -0.10071704 | BI5: -0.12578122 | BJ5: -0.010946697 | BK5: -0.061548923 | BL5: -0.15045858 | BM5: 0.12760274 | BN5: -0.017866803 | BO5: -0.025323955 | BP5: 0.040051232 | BQ5: -0.042262606 | BR5: 0.17888215 | BS5: -0.099129045 | BT5: 0.040560012 | BU5: 0.063241856 | BV5: -0.096181909 | BW5: -0.13606285 | BX5: -0.0050219314 | BY5: 0.11233989 | BZ5: 0.034223088 | CA5: 0.070051209 | CB5: 0.023662883 | CC5: 0.093938184 | CD5: -0.029913967 | CE5: -0.10685236 | CF5: -0.058583352 | CG5: -0.1185641 | CH5: -0.047815465 | CI5: -0.061561116 | CJ5: 0.22741941 | CK5: 0.1332388 | CL5: 0.040261514 | CM5: -0.073899374 | CN5: 0.24689459 | CO5: -0.10444084 | CP5: -0.017008494 | CQ5: -0.20843471 | CR5: -0.083953984 | CS5: 0.08662128 | CT5: -0.02628501 | CU5: -0.29981484 | CV5: 0.24030007 | CW5: 0.09157936 | CX5: -0.099166296 | CY5: 0.10766172 | CZ5: -0.054245194 | DA5: 0.08253219 | DB5: 0.13651007 | DC5: -0.013925396 | DD5: -0.13979564 | DE5: -0.09411437 | DF5: 0.052829966 | DG5: -0.19928626 | DH5: 0.10213914 | DI5: 0.037772798 | DJ5: 0.065447994 | DK5: 0.059654622 | DL5: 0.095335574 | DM5: 0.040485912 | DN5: 0.0034939953 | DO5: -0.10610844 | DP5: -0.24479189 | DQ5: 0.21383696 | DR5: 0.010889666 | DS5: 0.13411936 | DT5: 0.12417191 | DU5: 0.078095889 | DV5: -0.053915428 | DW5: -0.023828252 | DX5: 0.066514734 | DY5: 0.019361307 | DZ5: 0.018750008 | EA5: -0.28354334 | EB5: -0.13389241 | EC5: -0.022714427 | ED5: 0.044607042 | EE5: -0.129061 | EF5: -0.065742552 | EG5: -0.11722283 | EH5: -0.026547499 | EI5: -0.033015556 | EJ5: 0.045977173 | EK5: -0.069235534 | EL5: 0.014684336 | EM5: #NUM!
A6: 絕對值最大 | C6: {=MATCH(MAX(ABS(C3:C5)), ABS(C3:C5), 0)} -> 2 | D6: {=MATCH(MAX(ABS(D3:D5)), ABS(D3:D5), 0)} -> 2 | E6: {=MATCH(MAX(ABS(E3:E5)), ABS(E3:E5), 0)} -> 2 | F6: {=MATCH(MAX(ABS(F3:F5)), ABS(F3:F5), 0)} -> 2 | G6: {=MATCH(MAX(ABS(G3:G5)), ABS(G3:G5), 0)} -> 3 | H6: {=MATCH(MAX(ABS(H3:H5)), ABS(H3:H5), 0)} -> 2 | I6: {=MATCH(MAX(ABS(I3:I5)), ABS(I3:I5), 0)} -> 1 | J6: {=MATCH(MAX(ABS(J3:J5)), ABS(J3:J5), 0)} -> 1 | ... EM6: {=MATCH(MAX(ABS(EM3:EM5)), ABS(EM3:EM5), 0)} -> #NUM!
C7: =IF(C6=1,"bm",IF(C6=2,"size",IF(C6=3,"mom"))) -> size | D7: =IF(D6=1,"bm",IF(D6=2,"size",IF(D6=3,"mom"))) -> size | E7: =IF(E6=1,"bm",IF(E6=2,"size",IF(E6=3,"mom"))) -> size | F7: =IF(F6=1,"bm",IF(F6=2,"size",IF(F6=3,"mom"))) -> size | G7: =IF(G6=1,"bm",IF(G6=2,"size",IF(G6=3,"mom"))) -> mom | H7: =IF(H6=1,"bm",IF(H6=2,"size",IF(H6=3,"mom"))) -> size | I7: =IF(I6=1,"bm",IF(I6=2,"size",IF(I6=3,"mom"))) -> bm | J7: =IF(J6=1,"bm",IF(J6=2,"size",IF(J6=3,"mom"))) -> bm | ... EM7: =IF(EM6=1,"bm",IF(EM6=2,"size",IF(EM6=3,"mom"))) -> #NUM!
C8: =IF(C6=1,C3,IF(C6=2,C4,IF(C6=3,C5))) -> -0.26567505 | D8: =IF(D6=1,D3,IF(D6=2,D4,IF(D6=3,D5))) -> -0.26274582 | E8: =IF(E6=1,E3,IF(E6=2,E4,IF(E6=3,E5))) -> -0.078695496 | F8: =IF(F6=1,F3,IF(F6=2,F4,IF(F6=3,F5))) -> 0.065706805 | G8: =IF(G6=1,G3,IF(G6=2,G4,IF(G6=3,G5))) -> 0.098556491 | H8: =IF(H6=1,H3,IF(H6=2,H4,IF(H6=3,H5))) -> -0.090782629 | I8: =IF(I6=1,I3,IF(I6=2,I4,IF(I6=3,I5))) -> 0.19658042 | J8: =IF(J6=1,J3,IF(J6=2,J4,IF(J6=3,J5))) -> 0.123748 | ... EM8: =IF(EM6=1,EM3,IF(EM6=2,EM4,IF(EM6=3,EM5))) -> #NUM!
A10: 投資組合 | C10: 公司數 | D10: 1051
A11: 等分 | B11: 家數 | C11: 2013/12 | D11: 2014/01 | E11: 2014/02 | F11: 2014/03 | G11: 2014/04 | H11: 2014/05 | I11: 2014/06 | J11: 2014/07 | K11: 2014/08 | L11: 2014/09 | M11: 2014/10 | N11: 2014/11 | O11: 2014/12 | P11: 2015/01 | Q11: 2015/02 | R11: 2015/03 | S11: 2015/04 | T11: 2015/05 | U11: 2015/06 | V11: 2015/07 | W11: 2015/08 | X11: 2015/09 | Y11: 2015/10 | Z11: 2015/11 | AA11: 2015/12 | AB11: 2016/01 | AC11: 2016/02 | AD11: 2016/03 | AE11: 2016/04 | AF11: 2016/05 | AG11: 2016/06 | AH11: 2016/07 | AI11: 2016/08 | AJ11: 2016/09 | AK11: 2016/10 | AL11: 2016/11 | AM11: 2016/12 | AN11: 2017/01 | AO11: 2017/02 | AP11: 2017/03 | AQ11: 2017/04 | AR11: 2017/05 | AS11: 2017/06 | AT11: 2017/07 | AU11: 2017/08 | AV11: 2017/09 | AW11: 2017/10 | AX11: 2017/11 | AY11: 2017/12 | AZ11: 2018/01 | BA11: 2018/02 | BB11: 2018/03 | BC11: 2018/04 | BD11: 2018/05 | BE11: 2018/06 | BF11: 2018/07 | BG11: 2018/08 | BH11: 2018/09 | BI11: 2018/10 | BJ11: 2018/11 | BK11: 2018/12 | BL11: 2019/01 | BM11: 2019/02 | BN11: 2019/03 | BO11: 2019/04 | BP11: 2019/05 | BQ11: 2019/06 | BR11: 2019/07 | BS11: 2019/08 | BT11: 2019/09 | BU11: 2019/10 | BV11: 2019/11 | BW11: 2019/12 | BX11: 2020/01 | BY11: 2020/02 | BZ11: 2020/03 | CA11: 2020/04 | CB11: 2020/05 | CC11: 2020/06 | CD11: 2020/07 | CE11: 2020/08 | CF11: 2020/09 | CG11: 2020/10 | CH11: 2020/11 | CI11: 2020/12 | CJ11: 2021/01 | CK11: 2021/02 | CL11: 2021/03 | CM11: 2021/04 | CN11: 2021/05 | CO11: 2021/06 | CP11: 2021/07 | CQ11: 2021/08 | CR11: 2021/09 | CS11: 2021/10 | CT11: 2021/11 | CU11: 2021/12 | CV11: 2022/01 | CW11: 2022/02 | CX11: 2022/03 | CY11: 2022/04 | CZ11: 2022/05 | DA11: 2022/06 | DB11: 2022/07 | DC11: 2022/08 | DD11: 2022/09 | DE11: 2022/10 | DF11: 2022/11 | DG11: 2022/12 | DH11: 2023/01 | DI11: 2023/02 | DJ11: 2023/03 | DK11: 2023/04 | DL11: 2023/05 | DM11: 2023/06 | DN11: 2023/07 | DO11: 2023/08 | DP11: 2023/09 | DQ11: 2023/10 | DR11: 2023/11 | DS11: 2023/12 | DT11: 2024/01 | DU11: 2024/02 | DV11: 2024/03 | DW11: 2024/04 | DX11: 2024/05 | DY11: 2024/06 | DZ11: 2024/07 | EA11: 2024/08 | EB11: 2024/09 | EC11: 2024/10 | ED11: 2024/11 | EE11: 2024/12 | EF11: 2025/01 | EG11: 2025/02 | EH11: 2025/03 | EI11: 2025/04 | EJ11: 2025/05 | EK11: 2025/06 | EL11: 2025/07 | EM11: 平均值 | EN11: 標準差 | EO11: 夏普比率
A12: 10 | B12: =ROUND($D$10/A12,0) -> 105 | C12: 0.098199502 | D12: 0.1028238 | E12: 0.038261781 | F12: 0.0073451094 | G12: 0.03277276 | H12: 0.043063012 | I12: 0.046611964 | J12: 0.05668166 | K12: 0.028025433 | L12: 0.034533577 | M12: 0.034064795 | N12: 0.062468605 | O12: 0.026262839 | P12: 0.016299964 | Q12: 0.017014637 | R12: 0.0017251273 | S12: 0.040481856 | T12: 0.047307128 | U12: 0.020802966 | V12: 0.044981645 | W12: 0.058599399 | X12: 0.1204231 | Y12: 0.032478381 | Z12: 0.057530096 | AA12: 0.031866297 | AB12: 0.031101794 | AC12: 0.037252426 | AD12: 0.009132501 | AE12: 0.044953944 | AF12: 0.050075684 | AG12: 0.037657153 | AH12: 0.017150195 | AI12: 0.0077407002 | AJ12: 0.018902487 | AK12: 0.041114693 | AL12: 0.036103997 | AM12: 0.025435995 | AN12: 0.059852191 | AO12: 0.028904676 | AP12: 0.021539548 | AQ12: 0.014732134 | AR12: 0.030774647 | AS12: 0.029038603 | AT12: 0.071815369 | AU12: 0.06350953 | AV12: 0.059343045 | AW12: 0.011017888 | AX12: 0.055790314 | AY12: 0.02070539 | AZ12: 0.056338485 | BA12: 0.070623312 | BB12: 0.037731301 | BC12: 0.0037833204 | BD12: 0.050680413 | BE12: 0.027620677 | BF12: 0.045781102 | BG12: 0.05107324 | BH12: 0.034422221 | BI12: 0.058150961 | BJ12: 0.036180007 | BK12: 0.017434305 | BL12: 0.027124146 | BM12: 0.0403016 | BN12: 0.030037923 | BO12: 0.024587825 | BP12: 0.024810168 | BQ12: 0.005654826 | BR12: 0.059753167 | BS12: 0.02980301 | BT12: 0.02130586 | BU12: 0.035413041 | BV12: 0.034554758 | BW12: 0.038348648 | BX12: 0.018198986 | BY12: 0.051109523 | BZ12: 0.040874328 | CA12: 0.033013411 | CB12: 0.056271327 | CC12: 0.019545734 | CD12: 0.10131152 | CE12: 0.14141655 | CF12: 0.032181788 | CG12: 0.049661346 | CH12: 0.067832672 | CI12: 0.030588249 | CJ12: 0.058035853 | CK12: 0.060243584 | CL12: 0.15371706 | CM12: 0.06443083 | CN12: 0.097750475 | CO12: 0.068320871 | CP12: 0.04605124 | CQ12: 0.057210856 | CR12: 0.04794599 | CS12: 0.0052591904 | CT12: 0.031936085 | CU12: 0.076750601 | CV12: 0.068454073 | CW12: 0.02594707 | CX12: 0.070272156 | CY12: 0.026011705 | CZ12: 0.088361067 | DA12: 0.030372588 | DB12: 0.076905202 | DC12: 0.030502687 | DD12: 0.059350422 | DE12: 0.019852691 | DF12: 0.048904276 | DG12: 0.043686976 | DH12: 0.032463432 | DI12: 0.053725325 | DJ12: 0.021108185 | DK12: 0.034140901 | DL12: 0.026113587 | DM12: 0.021984778 | DN12: 0.030259151 | DO12: 0.023375644 | DP12: 0.067273187 | DQ12: 0.061902356 | DR12: 0.021610692 | DS12: 0.080446065 | DT12: 0.026928947 | DU12: 0.050063196 | DV12: 0.052446977 | DW12: 0.057897224 | DX12: 0.045674414 | DY12: 0.048289115 | DZ12: 0.013599532 | EA12: 0.11685074 | EB12: 0.028071677 | EC12: 0.026194942 | ED12: 0.061427254 | EE12: 0.028166727 | EF12: 0.021832482 | EG12: 0.097829678 | EH12: 0.022258683 | EI12: 0.0089612567 | EJ12: 0.068011014 | EK12: 0.050118013 | EL12: 0.049017881 | EM12: =AVERAGE(C12:EL12) -> 0.043800762 | EN12: =STDEV(C12:EL12) -> 0.02638634 | EO12: =EM12/EN12 -> 1.6599787
A13: 20 | B13: =ROUND($D$10/A13,0) -> 53 | C13: 0.12107776 | D13: 0.083505282 | E13: 0.049219109 | F13: 0.037987155 | G13: 0.016784224 | H13: 0.029251264 | I13: 0.049436102 | J13: 0.059989716 | K13: 0.017789949 | L13: 0.018673571 | M13: 0.014532356 | N13: 0.083003657 | O13: 0.016835251 | P13: 0.020395862 | Q13: 0.010565631 | R13: -0.0033304003 | S13: 0.067239971 | T13: 0.070405106 | U13: 0.014617996 | V13: 0.035925228 | W13: 0.079691017 | X13: 0.1392785 | Y13: 0.041377915 | Z13: 0.070580148 | AA13: 0.050692982 | AB13: 0.045772413 | AC13: 0.02706018 | AD13: -0.0030083609 | AE13: 0.065918726 | AF13: 0.067638222 | AG13: 0.043719681 | AH13: 0.0021139489 | AI13: 0.019590207 | AJ13: -0.0099915602 | AK13: 0.063693125 | AL13: 0.034676361 | AM13: 0.028672216 | AN13: 0.096939842 | AO13: 0.031449632 | AP13: 0.045398469 | AQ13: 0.01593738 | AR13: 0.033598562 | AS13: 0.034877568 | AT13: 0.094929152 | AU13: 0.07301813 | AV13: 0.096710764 | AW13: 0.016266122 | AX13: 0.052100773 | AY13: 0.0089780822 | AZ13: 0.065669863 | BA13: 0.073179702 | BB13: 0.016680253 | BC13: 0.0061704013 | BD13: 0.037273886 | BE13: 0.036756945 | BF13: 0.10528099 | BG13: 0.085439588 | BH13: 0.041179773 | BI13: 0.056277194 | BJ13: 0.046151926 | BK13: 0.032887619 | BL13: 0.038941059 | BM13: 0.046612516 | BN13: 0.027466363 | BO13: 0.041090335 | BP13: 0.020221679 | BQ13: 0.020671693 | BR13: 0.079435374 | BS13: 0.034048716 | BT13: 0.012182762 | BU13: 0.060633379 | BV13: 0.049478741 | BW13: 0.059954891 | BX13: 0.024517822 | BY13: 0.0488462 | BZ13: 0.067196131 | CA13: 0.026303578 | CB13: 0.11090423 | CC13: -0.0010716721 | CD13: 0.10225278 | CE13: 0.18420232 | CF13: 0.047483485 | CG13: 0.049202653 | CH13: 0.049554743 | CI13: 0.050093246 | CJ13: 0.069084695 | CK13: 0.065517118 | CL13: 0.16079609 | CM13: 0.082791769 | CN13: 0.11365842 | CO13: 0.079115499 | CP13: 0.066793736 | CQ13: 0.056641732 | CR13: 0.071519219 | CS13: 0.0098166213 | CT13: 0.028971683 | CU13: 0.11178805 | CV13: 0.076907356 | CW13: 0.033795594 | CX13: 0.079685442 | CY13: 0.056233686 | CZ13: 0.080348889 | DA13: 0.014829783 | DB13: 0.078082554 | DC13: 0.025165393 | DD13: 0.071693272 | DE13: 0.014632666 | DF13: 0.063934166 | DG13: 0.037529261 | DH13: 0.039090407 | DI13: 0.071009668 | DJ13: 0.0060368667 | DK13: 0.020804993 | DL13: 0.031928367 | DM13: 0.0080990213 | DN13: -0.00041533677 | DO13: 0.041067717 | DP13: 0.075241348 | DQ13: 0.061220596 | DR13: 0.020233317 | DS13: 0.071305965 | DT13: 0.027375113 | DU13: 0.01231375 | DV13: 0.072397715 | DW13: 0.058892837 | DX13: 0.060352983 | DY13: 0.087275153 | DZ13: 0.017528667 | EA13: 0.12694827 | EB13: 0.057080533 | EC13: 0.040940282 | ED13: 0.065938453 | EE13: 0.037157512 | EF13: 0.035981928 | EG13: 0.15154919 | EH13: -0.0034030753 | EI13: 0.01362226 | EJ13: 0.09123496 | EK13: 0.043586137 | EL13: 0.066108719 | EM13: =AVERAGE(C13:EL13) -> 0.05066138 | EN13: =STDEV(C13:EL13) -> 0.034735324 | EO13: =EM13/EN13 -> 1.4584974
A14: 50 | B14: =ROUND($D$10/A14,0) -> 21 | C14: 0.13220513 | D14: 0.1158128 | E14: 0.083639426 | F14: 0.047441584 | G14: 0.075085371 | H14: 0.076211003 | I14: 0.082313591 | J14: 0.064091148 | K14: 0.038115639 | L14: 0.036882667 | M14: -0.0022751694 | N14: 0.1459039 | O14: -0.006983831 | P14: 0.055715035 | Q14: 0.003587675 | R14: -0.0032911964 | S14: 0.13958411 | T14: 0.043640637 | U14: -0.018672251 | V14: 0.019356688 | W14: 0.10108001 | X14: 0.15214958 | Y14: 0.044544401 | Z14: 0.050537712 | AA14: 0.09685095 | AB14: 0.069227714 | AC14: -0.0022507861 | AD14: 0.006953009 | AE14: 0.10829638 | AF14: 0.076843366 | AG14: 0.028655986 | AH14: -0.01011933 | AI14: -0.027402986 | AJ14: 0.0077624249 | AK14: 0.058451123 | AL14: 0.042015348 | AM14: 0.050755743 | AN14: 0.10441557 | AO14: 0.032604668 | AP14: 0.054501731 | AQ14: 0.019665685 | AR14: 0.062379456 | AS14: -0.013478002 | AT14: 0.13781441 | AU14: 0.10970669 | AV14: 0.11071267 | AW14: 0.06525955 | AX14: 0.040769984 | AY14: 0.017193044 | AZ14: 0.0053410775 | BA14: 0.091311505 | BB14: 0.077818594 | BC14: 0.020523204 | BD14: 0.027350925 | BE14: 0.071812118 | BF14: 0.15729123 | BG14: 0.12707303 | BH14: 0.064711625 | BI14: 0.030087417 | BJ14: 0.024895583 | BK14: -0.021044327 | BL14: 0.032503786 | BM14: 0.032921165 | BN14: 0.011205903 | BO14: 0.024215816 | BP14: -0.048228295 | BQ14: 0.007465479 | BR14: 0.079846846 | BS14: 0.029611615 | BT14: -0.016902937 | BU14: 0.10739504 | BV14: 0.081081006 | BW14: 0.094813186 | BX14: -0.0039873386 | BY14: 0.098203766 | BZ14: 0.081435134 | CA14: -0.015300814 | CB14: 0.11179425 | CC14: 0.0094556516 | CD14: 0.08799128 | CE14: 0.20666802 | CF14: 0.077361646 | CG14: 0.065160968 | CH14: 0.058613307 | CI14: 0.11384421 | CJ14: 0.06143799 | CK14: 0.053942692 | CL14: 0.2064437 | CM14: 0.09007073 | CN14: 0.21436197 | CO14: 0.17790312 | CP14: 0.061247191 | CQ14: 0.016983986 | CR14: 0.04962061 | CS14: 0.012169087 | CT14: 0.074203932 | CU14: 0.13049332 | CV14: 0.13473975 | CW14: 0.041207943 | CX14: 0.078880627 | CY14: 0.10967162 | CZ14: 0.067028484 | DA14: 0.047399854 | DB14: 0.083638879 | DC14: 0.012420966 | DD14: 0.098734768 | DE14: 0.059073402 | DF14: 0.16325273 | DG14: 0.043741274 | DH14: 0.062926026 | DI14: 0.1289201 | DJ14: 0.013777168 | DK14: 0.035525439 | DL14: 0.039872633 | DM14: 0.019116465 | DN14: 0.042219255 | DO14: 0.067491555 | DP14: 0.082099873 | DQ14: 0.032645533 | DR14: 0.053613769 | DS14: 0.053892649 | DT14: 0.015125285 | DU14: 0.05484965 | DV14: 0.10495332 | DW14: 0.07629508 | DX14: 0.071555654 | DY14: 0.14810313 | DZ14: 0.013236455 | EA14: 0.068284483 | EB14: 0.084619817 | EC14: 0.017473935 | ED14: 0.098937326 | EE14: 0.012534993 | EF14: 0.059075573 | EG14: 0.21599687 | EH14: 0.0057072128 | EI14: 0.0056953674 | EJ14: 0.075260903 | EK14: 0.035700626 | EL14: 0.10022551 | EM14: =AVERAGE(C14:EL14) -> 0.062235722 | EN14: =STDEV(C14:EL14) -> 0.051599469 | EO14: =EM14/EN14 -> 1.2061311
A15: 110 | B15: =ROUND($D$10/A15,0) -> 10 | C15: 0.24155842 | D15: 0.17378891 | E15: 0.074569663 | F15: 0.081782027 | G15: 0.0025357798 | H15: 0.08181565 | I15: 0.12829638 | J15: 0.13535866 | K15: 0.031508098 | L15: -0.022753363 | M15: 0.056295859 | N15: 0.24738805 | O15: -0.018896543 | P15: 0.069494413 | Q15: -0.030677617 | R15: -0.053079677 | S15: 0.18023614 | T15: 0.058198487 | U15: -0.084116384 | V15: -0.017093663 | W15: 0.062669826 | X15: 0.20484096 | Y15: 0.021717268 | Z15: 0.03962135 | AA15: 0.1289089 | AB15: 0.074371814 | AC15: 0.048008146 | AD15: 0.013590293 | AE15: 0.17602317 | AF15: 0.1324867 | AG15: 0.024048006 | AH15: -0.037104176 | AI15: -0.018572528 | AJ15: 0.0097728322 | AK15: 0.057963941 | AL15: 0.028443609 | AM15: 0.034533292 | AN15: 0.11870397 | AO15: 0.043798347 | AP15: 0.037834339 | AQ15: -0.038102469 | AR15: 0.04832012 | AS15: -0.065028804 | AT15: 0.20783896 | AU15: 0.13494562 | AV15: 0.09108381 | AW15: 0.097211153 | AX15: 0.11407969 | AY15: 0.030135108 | AZ15: 0.032014302 | BA15: 0.16145099 | BB15: 0.13503031 | BC15: 0.067540884 | BD15: -0.020834013 | BE15: 0.063332839 | BF15: 0.2271004 | BG15: 0.10639437 | BH15: 0.095162128 | BI15: 0.044085978 | BJ15: 0.10657677 | BK15: -0.022584607 | BL15: 0.075891716 | BM15: 0.054492832 | BN15: -0.03567062 | BO15: 0.031395373 | BP15: -0.098443455 | BQ15: 0.015695153 | BR15: 0.11004284 | BS15: 0.003978778 | BT15: 0.012059676 | BU15: 0.053351351 | BV15: 0.063848423 | BW15: 0.31543556 | BX15: 0.043155484 | BY15: 0.1170215 | BZ15: 0.07695572 | CA15: 0.0060851496 | CB15: 0.064451767 | CC15: 0.10782726 | CD15: 0.1195227 | CE15: 0.12056337 | CF15: 0.078920462 | CG15: 0.10390932 | CH15: 0.067519779 | CI15: 0.037144945 | CJ15: 0.05487445 | CK15: 0.14342183 | CL15: 0.29060109 | CM15: 0.053281165 | CN15: 0.16864261 | CO15: 0.1646968 | CP15: 0.10300283 | CQ15: 0.0064482894 | CR15: 0.034388284 | CS15: 0.00900126 | CT15: 0.019878054 | CU15: 0.16039605 | CV15: 0.15883628 | CW15: 0.031169211 | CX15: 0.0626011 | CY15: 0.06815769 | CZ15: 0.090923793 | DA15: 0.068598068 | DB15: 0.039932393 | DC15: 0.017598376 | DD15: 0.066996804 | DE15: 0.07737662 | DF15: 0.29943563 | DG15: 0.040171633 | DH15: 0.13218755 | DI15: 0.020190924 | DJ15: 0.028863595 | DK15: 0.083677801 | DL15: 0.045174394 | DM15: 0.012983297 | DN15: 0.011986824 | DO15: 0.042035732 | DP15: 0.14986805 | DQ15: 0.02599177 | DR15: 0.025698175 | DS15: 0.052192903 | DT15: 0.022455457 | DU15: 0.083734456 | DV15: 0.14862276 | DW15: 0.0082263342 | DX15: 0.084800177 | DY15: 0.23875532 | DZ15: 0.034082281 | EA15: -0.037469676 | EB15: 0.11336525 | EC15: 0.082959084 | ED15: 0.14216139 | EE15: 0.0096175593 | EF15: 0.044912949 | EG15: 0.3447148 | EH15: -0.014955065 | EI15: 0.028455499 | EJ15: 0.083064683 | EK15: 0.03490671 | EL15: 0.097763681 | EM15: =AVERAGE(C15:EL15) -> 0.07221595 | EN15: =STDEV(C15:EL15) -> 0.077490328 | EO15: =EM15/EN15 -> 0.93193501
A16: 120 | B16: =ROUND($D$10/A16,0) -> 9 | C16: 0.26072771 | D16: 0.18425851 | E16: 0.074485661 | F16: 0.053057197 | G16: 0.088348382 | H16: 0.082581289 | I16: 0.13862835 | J16: 0.14986078 | K16: 0.029838912 | L16: -0.024637175 | M16: 0.053926092 | N16: 0.28291581 | O16: -0.029371948 | P16: 0.071716708 | Q16: -0.0026762679 | R16: -0.062293903 | S16: 0.19622946 | T16: 0.094226726 | U16: -0.071987231 | V16: -0.00052208373 | W16: 0.048227746 | X16: 0.18341156 | Y16: 0.026871903 | Z16: 0.026245552 | AA16: 0.12915152 | AB16: 0.083679344 | AC16: 0.059916162 | AD16: 0.018883824 | AE16: 0.19437017 | AF16: 0.14270118 | AG16: 0.030984763 | AH16: -0.0317654 | AI16: -0.025151214 | AJ16: -0.030488409 | AK16: 0.064421401 | AL16: 0.024777898 | AM16: 0.028591226 | AN16: 0.13740291 | AO16: 0.063928703 | AP16: 0.062955476 | AQ16: -0.051655017 | AR16: 0.10277024 | AS16: -0.065720092 | AT16: 0.22132084 | AU16: 0.13870065 | AV16: 0.089459285 | AW16: 0.1131797 | AX16: 0.1135956 | AY16: 0.040307501 | AZ16: 0.026619999 | BA16: 0.15831023 | BB16: 0.18136461 | BC16: 0.065392331 | BD16: -0.025047737 | BE16: 0.055749585 | BF16: 0.13590411 | BG16: 0.10367992 | BH16: 0.12147275 | BI16: 0.040348435 | BJ16: 0.11634242 | BK16: -0.036488351 | BL16: 0.069396399 | BM16: 0.044461594 | BN16: -0.021653837 | BO16: 0.025701079 | BP16: -0.044135395 | BQ16: 0.016526034 | BR16: 0.11314364 | BS16: -0.0079012392 | BT16: 0.012797701 | BU16: 0.04248524 | BV16: 0.037578374 | BW16: 0.33664394 | BX16: 0.046677909 | BY16: 0.13162601 | BZ16: 0.10500368 | CA16: 0.0221427 | CB16: 0.065264696 | CC16: 0.11825016 | CD16: 0.11570921 | CE16: 0.069763241 | CF16: 0.082940336 | CG16: 0.11597682 | CH16: 0.048054505 | CI16: 0.049089741 | CJ16: 0.030955417 | CK16: 0.1414699 | CL16: 0.3115428 | CM16: 0.052124071 | CN16: 0.17176381 | CO16: 0.18300397 | CP16: 0.11273963 | CQ16: 0.075659969 | CR16: 0.030724192 | CS16: 0.0100014 | CT16: 0.028909286 | CU16: 0.15928631 | CV16: 0.13244233 | CW16: 0.055800521 | CX16: 0.058083728 | CY16: 0.078936117 | CZ16: 0.11871138 | DA16: 0.095888549 | DB16: 0.057360445 | DC16: 0.015595176 | DD16: 0.081763272 | DE16: 0.052450111 | DF16: 0.32192975 | DG16: 0.044449393 | DH16: 0.15270632 | DI16: 0.043303131 | DJ16: 0.038300463 | DK16: 0.083260594 | DL16: 0.0096269309 | DM16: -0.036759747 | DN16: 0.022233967 | DO16: 0.05537644 | DP16: 0.146368 | DQ16: 0.024838896 | DR16: 0.037831497 | DS16: 0.052113583 | DT16: 0.058933335 | DU16: 0.085341215 | DV16: 0.15138813 | DW16: 0.037742997 | DX16: 0.064285001 | DY16: 0.24509916 | DZ16: 0.046178941 | EA16: 0.015304943 | EB16: 0.11109854 | EC16: 0.082284542 | ED16: 0.14742157 | EE16: 0.011537607 | EF16: 0.06024264 | EG16: 0.39578696 | EH16: -0.02327539 | EI16: 0.02581173 | EJ16: 0.077611135 | EK16: 0.03627353 | EL16: 0.094527384 | EM16: =AVERAGE(C16:EL16) -> 0.077314032 | EN16: =STDEV(C16:EL16) -> 0.080606755 | EO16: =EM16/EN16 -> 0.95915077
A17: 130 | B17: =ROUND($D$10/A17,0) -> 8 | C17: 0.23789705 | D17: 0.18133129 | E17: 0.076702626 | F17: 0.056491027 | G17: 0.088781682 | H17: 0.039953295 | I17: 0.15376841 | J17: 0.15964101 | K17: 0.016624608 | L17: -0.0074515064 | M17: 0.055237105 | N17: 0.31927896 | O17: -0.024067294 | P17: 0.077831432 | Q17: 0.0079022645 | R17: -0.068471776 | S17: 0.2459656 | T17: 0.093876727 | U17: -0.073605682 | V17: 0.010198759 | W17: 0.045379488 | X17: 0.17625246 | Y17: 0.033272864 | Z17: 0.034849786 | AA17: 0.15968294 | AB17: 0.085885231 | AC17: 0.056501261 | AD17: -0.029598498 | AE17: 0.17483925 | AF17: 0.18161714 | AG17: 0.066435099 | AH17: -0.049437542 | AI17: -0.0011848961 | AJ17: -0.042250027 | AK17: 0.031812486 | AL17: 0.034172977 | AM17: 0.044527644 | AN17: 0.11503171 | AO17: 0.029150084 | AP17: 0.085202771 | AQ17: -0.033097297 | AR17: 0.054951162 | AS17: -0.086099673 | AT17: 0.26750173 | AU17: 0.13777321 | AV17: 0.056706305 | AW17: 0.12680047 | AX17: 0.096011083 | AY17: 0.03862585 | AZ17: 0.026112753 | BA17: 0.1683477 | BB17: 0.20214347 | BC17: 0.081917918 | BD17: -0.01583429 | BE17: 0.079146429 | BF17: 0.14947847 | BG17: 0.089104615 | BH17: 0.12412671 | BI17: 0.024448209 | BJ17: 0.12527426 | BK17: -0.040770554 | BL17: 0.043403096 | BM17: 0.023685773 | BN17: -0.017785292 | BO17: 0.01026863 | BP17: -0.051687061 | BQ17: 0.039513526 | BR17: 0.12604134 | BS17: -0.0092324974 | BT17: 0.0012266991 | BU17: 0.071890941 | BV17: 0.065900934 | BW17: 0.38902933 | BX17: 0.051844993 | BY17: 0.09546082 | BZ17: 0.11817692 | CA17: 0.019416681 | CB17: 0.066333613 | CC17: 0.18432007 | CD17: 0.14623125 | CE17: 0.088883514 | CF17: 0.075392684 | CG17: 0.12327028 | CH17: 0.08287238 | CI17: 0.055913289 | CJ17: 0.017740045 | CK17: 0.14304347 | CL17: 0.3402882 | CM17: 0.038686091 | CN17: 0.13461178 | CO17: 0.13711923 | CP17: 0.12017581 | CQ17: 0.066152951 | CR17: 0.029283681 | CS17: 0.032669997 | CT17: 0.039818933 | CU17: 0.15469155 | CV17: 0.12279516 | CW17: 0.06956224 | CX17: 0.049065006 | CY17: 0.046190211 | CZ17: 0.16623878 | DA17: 0.084473678 | DB17: 0.058532683 | DC17: 0.025802332 | DD17: 0.096005186 | DE17: 0.020616317 | DF17: 0.34811953 | DG17: 0.050927878 | DH17: 0.17700917 | DI17: 0.05902996 | DJ17: 0.040386118 | DK17: 0.095776785 | DL17: 0.0033776522 | DM17: -0.043442597 | DN17: 0.054541208 | DO17: 0.07516469 | DP17: 0.17925711 | DQ17: 0.047643837 | DR17: 0.05372812 | DS17: 0.040247977 | DT17: 0.076728353 | DU17: 0.094942711 | DV17: 0.16779805 | DW17: 0.025002201 | DX17: 0.072360521 | DY17: 0.25068056 | DZ17: 0.033849734 | EA17: 0.009396136 | EB17: 0.12095982 | EC17: 0.056703449 | ED17: 0.16432987 | EE17: 0.02611294 | EF17: 0.07172012 | EG17: 0.44216671 | EH17: -0.020238807 | EI17: 0.022829268 | EJ17: 0.076872405 | EK17: 0.044324995 | EL17: 0.093526203 | EM17: =AVERAGE(C17:EL17) -> 0.081131888 | EN17: =STDEV(C17:EL17) -> 0.087920383 | EO17: =EM17/EN17 -> 0.92278815
A18: 150 | B18: =ROUND($D$10/A18,0) -> 7 | C18: 0.24368729 | D18: 0.19928275 | E18: 0.10018499 | F18: 0.029665957 | G18: 0.075490668 | H18: 0.062052684 | I18: 0.14821157 | J18: 0.19319963 | K18: 0.045576886 | L18: -0.0473979 | M18: 0.053938886 | N18: 0.36380387 | O18: -0.00051258915 | P18: 0.064985121 | Q18: -0.019624524 | R18: -0.07653748 | S18: 0.28114322 | T18: 0.088495999 | U18: -0.06371502 | V18: 0.017150908 | W18: 0.050611891 | X18: 0.22365035 | Y18: 0.041263726 | Z18: 0.079093475 | AA18: 0.14275687 | AB18: 0.094821421 | AC18: 0.068592044 | AD18: -0.026866366 | AE18: 0.20233266 | AF18: 0.23353329 | AG18: 0.055242557 | AH18: -0.040197461 | AI18: 0.014126981 | AJ18: -0.042673163 | AK18: -0.002187481 | AL18: 0.051371435 | AM18: 0.032364638 | AN18: 0.1272885 | AO18: 0.0130722 | AP18: 0.086893121 | AQ18: 0.0069686748 | AR18: 0.060067609 | AS18: -0.034980857 | AT18: 0.2975536 | AU18: 0.13825374 | AV18: 0.036288329 | AW18: 0.18435776 | AX18: 0.13848386 | AY18: 0.087330041 | AZ18: 0.04134964 | BA18: 0.17834058 | BB18: 0.22902924 | BC18: 0.082288825 | BD18: -0.010232032 | BE18: 0.07597797 | BF18: 0.14387298 | BG18: 0.063329549 | BH18: 0.12438676 | BI18: 0.038239825 | BJ18: 0.0227653 | BK18: -0.040177172 | BL18: 0.059180796 | BM18: 0.047064733 | BN18: -0.020448989 | BO18: 0.020516468 | BP18: -0.058439021 | BQ18: 0.016229383 | BR18: 0.10983754 | BS18: -0.0087511588 | BT18: -0.0035308846 | BU18: 0.089383805 | BV18: -0.0095384602 | BW18: 0.43068383 | BX18: 0.035209839 | BY18: 0.087918547 | BZ18: 0.15079709 | CA18: 0.023223984 | CB18: 0.07872429 | CC18: 0.21996525 | CD18: 0.16567419 | CE18: 0.069460899 | CF18: 0.092314423 | CG18: 0.17068848 | CH18: 0.10811341 | CI18: 0.03025441 | CJ18: 0.00082733433 | CK18: 0.14910622 | CL18: 0.36775012 | CM18: 0.023792103 | CN18: 0.1687112 | CO18: 0.16749636 | CP18: 0.13085801 | CQ18: 0.047890905 | CR18: 0.038174056 | CS18: 0.043224755 | CT18: 0.030788312 | CU18: 0.16723456 | CV18: 0.10583157 | CW18: 0.081713486 | CX18: 0.052648091 | CY18: 0.065170046 | CZ18: 0.2000288 | DA18: 0.076047417 | DB18: 0.05554653 | DC18: 0.016338911 | DD18: 0.063134171 | DE18: 0.040133907 | DF18: 0.36199941 | DG18: 0.061064663 | DH18: 0.20586588 | DI18: 0.057437414 | DJ18: 0.047666267 | DK18: 0.067768733 | DL18: 0.0036194321 | DM18: -0.038027462 | DN18: 0.022669505 | DO18: 0.04152947 | DP18: 0.1930815 | DQ18: 0.037166409 | DR18: 0.052098328 | DS18: 0.014585284 | DT18: 0.095508567 | DU18: 0.11917142 | DV18: 0.19266368 | DW18: 0.05781256 | DX18: 0.062595078 | DY18: 0.27859859 | DZ18: 0.0011714753 | EA18: -0.017945666 | EB18: 0.10907789 | EC18: 0.05186524 | ED18: 0.16122649 | EE18: 0.020407386 | EF18: 0.082038992 | EG18: 0.49174202 | EH18: -0.023474761 | EI18: 0.014951567 | EJ18: 0.052617469 | EK18: 0.045567285 | EL18: 0.044722641 | EM18: =AVERAGE(C18:EL18) -> 0.085667788 | EN18: =STDEV(C18:EL18) -> 0.098236878 | EO18: =EM18/EN18 -> 0.87205324
A19: 180 | B19: =ROUND($D$10/A19,0) -> 6 | C19: 0.25825037 | D19: 0.20816772 | E19: 0.073818854 | F19: 0.018539269 | G19: 0.11281383 | H19: 0.08653379 | I19: 0.18313299 | J19: 0.2060553 | K19: 0.04288124 | L19: -0.053179775 | M19: 0.056587152 | N19: 0.41276888 | O19: 0.051189915 | P19: 0.08090003 | Q19: -0.050602909 | R19: -0.090299091 | S19: 0.32455081 | T19: 0.070706363 | U19: -0.064758127 | V19: 0.0054719785 | W19: 0.015187091 | X19: 0.22802403 | Y19: 0.041111502 | Z19: 0.079788074 | AA19: 0.10241977 | AB19: 0.079004586 | AC19: 0.048961984 | AD19: -0.041380571 | AE19: 0.23675418 | AF19: 0.24569995 | AG19: 0.048677234 | AH19: -0.056557715 | AI19: 0.031554436 | AJ19: -0.046836086 | AK19: 0.0075520425 | AL19: 0.059399001 | AM19: 0.032585017 | AN19: 0.11732234 | AO19: 0.023521152 | AP19: 0.095720651 | AQ19: 0.0018043551 | AR19: 0.061340989 | AS19: -0.057025232 | AT19: 0.33000222 | AU19: 0.15211368 | AV19: 0.040899919 | AW19: 0.20316137 | AX19: 0.18062021 | AY19: 0.090833527 | AZ19: 0.054875564 | BA19: 0.18450106 | BB19: 0.28755667 | BC19: 0.082725621 | BD19: -0.020372363 | BE19: 0.081058889 | BF19: 0.13026631 | BG19: -0.015144015 | BH19: 0.12966873 | BI19: 0.062583964 | BJ19: 0.024018118 | BK19: -0.089766859 | BL19: 0.067122935 | BM19: 0.049110781 | BN19: -0.013391265 | BO19: 0.02101985 | BP19: -0.068391037 | BQ19: 0.033457615 | BR19: 0.12323953 | BS19: -0.0089670616 | BT19: -0.035563239 | BU19: 0.09834372 | BV19: -0.04963926 | BW19: 0.35651024 | BX19: 0.012701726 | BY19: 0.094645219 | BZ19: 0.060872017 | CA19: 0.022382909 | CB19: 0.013789671 | CC19: 0.24176329 | CD19: 0.1634234 | CE19: 0.037209123 | CF19: 0.057049273 | CG19: 0.14129642 | CH19: 0.12967081 | CI19: 0.026363132 | CJ19: 0.0018728497 | CK19: 0.15223797 | CL19: 0.39173754 | CM19: 0.024237295 | CN19: 0.20357545 | CO19: 0.18612998 | CP19: 0.16282924 | CQ19: 0.046129026 | CR19: 0.036247753 | CS19: 0.055060465 | CT19: 0.036441796 | CU19: 0.17077279 | CV19: 0.13455717 | CW19: 0.067731066 | CX19: 0.1188798 | CY19: 0.072991215 | CZ19: 0.22268516 | DA19: 0.044898319 | DB19: 0.058652618 | DC19: -0.058594249 | DD19: 0.032007773 | DE19: 0.086484227 | DF19: 0.20002704 | DG19: 0.066791453 | DH19: 0.24633455 | DI19: 0.076023014 | DJ19: 0.050612658 | DK19: 0.062506167 | DL19: -0.0051896576 | DM19: -0.065564814 | DN19: 0.032923718 | DO19: 0.039010652 | DP19: 0.18722171 | DQ19: 0.050447793 | DR19: 0.050246246 | DS19: 0.00044112623 | DT19: 0.073921319 | DU19: 0.11597873 | DV19: 0.17771197 | DW19: 0.075899946 | DX19: 0.067368661 | DY19: 0.26829386 | DZ19: 0.027232235 | EA19: 0.0077747406 | EB19: 0.1203181 | EC19: 0.035933992 | ED19: 0.19894255 | EE19: 0.030408355 | EF19: 0.072902632 | EG19: 0.58220862 | EH19: -0.071339264 | EI19: -0.020693682 | EJ19: 0.057543775 | EK19: 0.041623588 | EL19: 0.044033342 | EM19: =AVERAGE(C19:EL19) -> 0.085123144 | EN19: =STDEV(C19:EL19) -> 0.10710804 | EO19: =EM19/EN19 -> 0.79474092
A20: 200 | B20: =ROUND($D$10/A20,0) -> 5 | C20: 0.24103575 | D20: 0.22395276 | E20: 0.048815066 | F20: -0.027411849 | G20: 0.13326717 | H20: 0.12733286 | I20: 0.2142285 | J20: 0.22900575 | K20: 0.080698574 | L20: -0.057745399 | M20: 0.043807329 | N20: 0.4793614 | O20: 0.042734025 | P20: 0.094817749 | Q20: -0.026830945 | R20: -0.10925306 | S20: 0.27746771 | T20: 0.092488242 | U20: -0.044860999 | V20: 0.033003556 | W20: -0.0051830151 | X20: 0.19290231 | Y20: 0.042626995 | Z20: 0.091419716 | AA20: 0.095415529 | AB20: 0.11522085 | AC20: 0.065352664 | AD20: 0.0074482705 | AE20: 0.14193566 | AF20: 0.23868404 | AG20: 0.027659219 | AH20: -0.090178201 | AI20: 0.030638749 | AJ20: -0.061990035 | AK20: -0.013595115 | AL20: 0.06732844 | AM20: 0.035351237 | AN20: 0.12084147 | AO20: 0.033309502 | AP20: 0.086745238 | AQ20: -0.022718044 | AR20: 0.062905685 | AS20: -0.073246356 | AT20: 0.20306259 | AU20: 0.17397435 | AV20: 0.026086323 | AW20: 0.26649662 | AX20: 0.17901395 | AY20: 0.11224017 | AZ20: 0.050576081 | BA20: 0.21454655 | BB20: 0.29812631 | BC20: 0.0395224 | BD20: -0.015998214 | BE20: 0.05420768 | BF20: 0.15957317 | BG20: 0.0012954825 | BH20: 0.09101886 | BI20: 0.089047958 | BJ20: 0.019418236 | BK20: -0.044707859 | BL20: 0.074609524 | BM20: 0.056480863 | BN20: -0.036520911 | BO20: 0.023612563 | BP20: -0.00070586227 | BQ20: 0.042904947 | BR20: 0.15807728 | BS20: -0.02436463 | BT20: -0.057929858 | BU20: 0.10665679 | BV20: -0.057447555 | BW20: 0.42242582 | BX20: -0.016073797 | BY20: 0.09275567 | BZ20: 0.086739353 | CA20: 0.017341988 | CB20: 0.022364425 | CC20: 0.26709573 | CD20: 0.17836063 | CE20: 0.032857624 | CF20: 0.065930866 | CG20: 0.13171375 | CH20: 0.1391514 | CI20: -0.0041774733 | CJ20: -0.051555945 | CK20: 0.11339293 | CL20: 0.39075319 | CM20: 0.0083382579 | CN20: 0.10407991 | CO20: 0.21784067 | CP20: 0.15236924 | CQ20: 0.045176644 | CR20: 0.045103738 | CS20: 0.035040748 | CT20: 0.057906913 | CU20: 0.16194417 | CV20: 0.15168961 | CW20: 0.053587192 | CX20: 0.12069465 | CY20: 0.090125293 | CZ20: 0.20179986 | DA20: 0.022041977 | DB20: 0.07696807 | DC20: -0.034561131 | DD20: 0.034565162 | DE20: 0.067537504 | DF20: 0.22982781 | DG20: 0.074371572 | DH20: 0.30439257 | DI20: 0.12416072 | DJ20: 0.11771965 | DK20: 0.07330978 | DL20: 0.0054649496 | DM20: -0.0075266043 | DN20: 0.045053325 | DO20: -0.01785512 | DP20: 0.17009872 | DQ20: 0.041618122 | DR20: 0.058604563 | DS20: -0.028698637 | DT20: 0.068042387 | DU20: 0.1160416 | DV20: 0.20180049 | DW20: 0.074901762 | DX20: 0.068670561 | DY20: 0.33206307 | DZ20: 0.029062312 | EA20: 0.0020601827 | EB20: 0.13359364 | EC20: 0.051561124 | ED20: 0.20700659 | EE20: 0.034307819 | EF20: 0.084458715 | EG20: 0.6428665 | EH20: -0.08616221 | EI20: -0.016322785 | EJ20: 0.037389857 | EK20: 0.049176622 | EL20: -0.016442584 | EM20: =AVERAGE(C20:EL20) -> 0.087097175 | EN20: =STDEV(C20:EL20) -> 0.11372608 | EO20: =EM20/EN20 -> 0.76585052
A21: 256 | B21: =ROUND($D$10/A21,0) -> 4 | C21: 0.24900647 | D21: 0.18724832 | E21: 0.070282274 | F21: 0.069409277 | G21: 0.062455603 | H21: 0.083509199 | I21: 0.21735428 | J21: 0.2850354 | K21: 0.064334981 | L21: -0.04172274 | M21: -0.029350118 | N21: 0.58489126 | O21: 0.05885514 | P21: 0.1103949 | Q21: 0.017744004 | R21: -0.095575311 | S21: 0.2546828 | T21: 0.11571896 | U21: -0.015792012 | V21: 0.019105437 | W21: -0.031960015 | X21: 0.19383702 | Y21: 0.094011996 | Z21: 0.096457432 | AA21: 0.092108182 | AB21: 0.11670997 | AC21: 0.06611486 | AD21: 0.01697952 | AE21: 0.15043393 | AF21: 0.2427615 | AG21: 0.044302778 | AH21: -0.10758136 | AI21: -0.022718914 | AJ21: -0.070405342 | AK21: -0.030643434 | AL21: 0.11096215 | AM21: 0.051301939 | AN21: 0.10643114 | AO21: 0.18036049 | AP21: 0.10480817 | AQ21: -0.046577566 | AR21: 0.087781597 | AS21: -0.11741732 | AT21: 0.21118407 | AU21: 0.1963969 | AV21: 0.013890262 | AW21: 0.28277325 | AX21: 0.15731136 | AY21: 0.13897813 | AZ21: 0.061468477 | BA21: 0.16630847 | BB21: 0.41331183 | BC21: 0.059896201 | BD21: 0.0077711636 | BE21: 0.13674536 | BF21: 0.19911722 | BG21: -0.093639109 | BH21: 0.1747792 | BI21: 0.059055113 | BJ21: 0.021522475 | BK21: -0.072723115 | BL21: 0.094508283 | BM21: 0.040795286 | BN21: -0.039097178 | BO21: -0.10661704 | BP21: 0.0072557031 | BQ21: 0.058010345 | BR21: 0.13736323 | BS21: -0.029758593 | BT21: -0.090003492 | BU21: 0.12746595 | BV21: -0.082098962 | BW21: 0.54260973 | BX21: -0.033159726 | BY21: 0.076881614 | BZ21: 0.093741646 | CA21: 0.064338154 | CB21: 0.036725783 | CC21: 0.17931875 | CD21: 0.24407683 | CE21: 0.031129962 | CF21: 0.054182445 | CG21: 0.1528728 | CH21: 0.00029607807 | CI21: -0.0030038033 | CJ21: -0.019661774 | CK21: 0.23663133 | CL21: 0.46678162 | CM21: -0.038292791 | CN21: 0.16385132 | CO21: 0.2413941 | CP21: 0.18306963 | CQ21: 0.04707242 | CR21: 0.041319889 | CS21: -0.031863383 | CT21: 0.067406807 | CU21: 0.17793682 | CV21: 0.20039656 | CW21: 0.043841589 | CX21: 0.14011729 | CY21: 0.11065031 | CZ21: 0.29550478 | DA21: 0.018335652 | DB21: 0.071461214 | DC21: -0.05244865 | DD21: 0.033671196 | DE21: 0.032131777 | DF21: 0.28613086 | DG21: 0.050042124 | DH21: 0.35821167 | DI21: 0.15186657 | DJ21: 0.11885608 | DK21: 0.076846385 | DL21: 0.021920189 | DM21: -0.024201303 | DN21: 0.029428371 | DO21: 0.01406641 | DP21: 0.11489911 | DQ21: 0.10920828 | DR21: 0.01851543 | DS21: -0.011682443 | DT21: -0.007893933 | DU21: 0.087036162 | DV21: 0.26431885 | DW21: 0.10898332 | DX21: 0.079471504 | DY21: 0.33648536 | DZ21: 0.014748174 | EA21: -0.053623856 | EB21: 0.089072393 | EC21: 0.054546207 | ED21: 0.092108523 | EE21: 0.031907537 | EF21: 0.08441724 | EG21: 0.76549825 | EH21: -0.053789794 | EI21: -0.0022718701 | EJ21: 0.024361895 | EK21: 0.0684961 | EL21: 0.026006532 | EM21: =AVERAGE(C21:EL21) -> 0.093149442 | EN21: =STDEV(C21:EL21) -> 0.13465774 | EO21: =EM21/EN21 -> 0.69174964
A22: 400 | B22: =ROUND($D$10/A22,0) -> 3 | C22: 0.28886619 | D22: 0.036573722 | E22: -0.017355099 | F22: 0.13986745 | G22: 0.10388436 | H22: 0.068510694 | I22: 0.21695806 | J22: 0.37609347 | K22: 0.02865678 | L22: 0.0039536714 | M22: -0.016096387 | N22: 0.75614344 | O22: 0.084166449 | P22: 0.026945954 | Q22: 0.034657141 | R22: -0.036628434 | S22: 0.072840827 | T22: 0.13585715 | U22: -0.044683532 | V22: 0.051797092 | W22: -0.032845179 | X22: 0.15785005 | Y22: 0.14950845 | Z22: 0.074601572 | AA22: 0.052507972 | AB22: 0.11750158 | AC22: 0.093396379 | AD22: 0.0089391604 | AE22: 0.13325425 | AF22: 0.27237225 | AG22: 0.05284154 | AH22: -0.10586596 | AI22: 0.020499608 | AJ22: -0.031699849 | AK22: 0.10128856 | AL22: 0.036840806 | AM22: 0.084088903 | AN22: 0.1772072 | AO22: 0.23610215 | AP22: 0.18456059 | AQ22: -0.17906239 | AR22: 0.082546725 | AS22: -0.022170482 | AT22: 0.11360434 | AU22: 0.27983615 | AV22: 0.079203229 | AW22: 0.41689457 | AX22: -0.047737841 | AY22: 0.1943425 | AZ22: 0.063956461 | BA22: 0.17858893 | BB22: 0.49016727 | BC22: -0.11554173 | BD22: 0.038662233 | BE22: 0.12806788 | BF22: 0.19910245 | BG22: -0.14297035 | BH22: 0.12770701 | BI22: -0.017540795 | BJ22: -0.0185016 | BK22: -0.048315241 | BL22: 0.11765695 | BM22: 0.0024304832 | BN22: -0.045815705 | BO22: -0.092277714 | BP22: 0.0023376902 | BQ22: 0.077351978 | BR22: 0.1469567 | BS22: 0.044078423 | BT22: -0.10520092 | BU22: 0.15266741 | BV22: -0.047266465 | BW22: 0.31056566 | BX22: -0.031911449 | BY22: 0.050267437 | BZ22: 0.041370983 | CA22: 0.046015862 | CB22: 0.043804174 | CC22: 0.27544482 | CD22: 0.3556731 | CE22: 0.013503449 | CF22: 0.1025081 | CG22: 0.32392308 | CH22: -0.026427163 | CI22: -0.015860418 | CJ22: -0.010540719 | CK22: 0.17643921 | CL22: 0.49541388 | CM22: -0.047372368 | CN22: 0.18215713 | CO22: 0.1715297 | CP22: 0.20656798 | CQ22: 0.092165908 | CR22: 0.0447396 | CS22: -0.068236067 | CT22: 0.095120869 | CU22: 0.19271417 | CV22: 0.23628081 | CW22: -0.010226546 | CX22: 0.12678553 | CY22: 0.13548943 | CZ22: 0.35215157 | DA22: 0.022473098 | DB22: 0.054041622 | DC22: -0.02408346 | DD22: 0.13835465 | DE22: -0.017756504 | DF22: 0.38966763 | DG22: 0.074791032 | DH22: 0.12640435 | DI22: 0.22468947 | DJ22: 0.10351464 | DK22: 0.072696131 | DL22: 0.033109115 | DM22: -0.023144336 | DN22: 0.010117601 | DO22: -0.061460673 | DP22: 0.088552486 | DQ22: 0.21106094 | DR22: -0.057297033 | DS22: -0.039948517 | DT22: 0.038469138 | DU22: 0.10201901 | DV22: 0.29109562 | DW22: -0.081415413 | DX22: 0.08318424 | DY22: 0.24344283 | DZ22: -0.0021797216 | EA22: -0.05422664 | EB22: 0.20437536 | EC22: 0.045053778 | ED22: 0.12755979 | EE22: 0.0016702628 | EF22: 0.034354893 | EG22: 0.94008944 | EH22: -0.090196327 | EI22: 0.0098367297 | EJ22: 0.062733872 | EK22: 0.1079891 | EL22: 0.047714946 | EM22: =AVERAGE(C22:EL22) -> 0.096036629 | EN22: =STDEV(C22:EL22) -> 0.15496649 | EO22: =EM22/EN22 -> 0.61972513
A23: 512 | B23: =ROUND($D$10/A23,0) -> 2 | C23: 0.28298927 | D23: 0.025572739 | E23: 0.13300519 | F23: 0.0037402329 | G23: -0.026971569 | H23: -0.018188471 | I23: 0.14815203 | J23: 0.11203535 | K23: -0.059917885 | L23: -0.050770834 | M23: -0.066725324 | N23: 0.97590144 | O23: -0.0023021518 | P23: 0.0033889195 | Q23: 0.067091137 | R23: -0.056211143 | S23: 0.084011483 | T23: 0.039614189 | U23: -0.19395986 | V23: 0.054692462 | W23: 0.0041345118 | X23: 0.18178119 | Y23: 0.23418396 | Z23: 0.13179101 | AA23: 0.13010524 | AB23: 0.15024155 | AC23: 0.097299095 | AD23: 0.042570963 | AE23: 0.15243654 | AF23: 0.19177289 | AG23: 0.091873658 | AH23: -0.084171585 | AI23: 0.030243744 | AJ23: 0.0481956 | AK23: 0.1141111 | AL23: 0.050760011 | AM23: 0.007769489 | AN23: 0.2423147 | AO23: 0.24640716 | AP23: 0.092917767 | AQ23: -0.18719278 | AR23: 0.14613616 | AS23: -0.062783844 | AT23: 0.1095059 | AU23: 0.31867753 | AV23: 0.15047651 | AW23: 0.091470967 | AX23: -0.014812779 | AY23: 0.17023398 | AZ23: 0.078071577 | BA23: 0.053998339 | BB23: 0.48557915 | BC23: -0.30082825 | BD23: 0.065076817 | BE23: 0.12429214 | BF23: 0.21000911 | BG23: -0.27238302 | BH23: 0.063365196 | BI23: 0.08141688 | BJ23: -0.046193151 | BK23: -0.047849323 | BL23: 0.11436629 | BM23: -0.069495462 | BN23: -0.15467717 | BO23: -0.19280643 | BP23: -0.009863038 | BQ23: 0.10425946 | BR23: 0.13241533 | BS23: -0.00049110058 | BT23: 0.10807709 | BU23: 0.23163287 | BV23: -0.053269051 | BW23: 0.31868519 | BX23: -0.083160926 | BY23: 0.083991021 | BZ23: -0.072330498 | CA23: 0.11584797 | CB23: 0.05611433 | CC23: 0.44318287 | CD23: 0.45821457 | CE23: -0.014933939 | CF23: 0.16761438 | CG23: 0.39327675 | CH23: -0.073046098 | CI23: 0.0056784922 | CJ23: -0.0021967846 | CK23: 0.31480429 | CL23: 0.34053143 | CM23: 0.019919502 | CN23: 0.29632285 | CO23: 0.16683225 | CP23: 0.23209987 | CQ23: 0.11133205 | CR23: 0.0016288977 | CS23: 0.0052840662 | CT23: 0.10388496 | CU23: 0.24014428 | CV23: 0.3097785 | CW23: -0.019053529 | CX23: -0.042852381 | CY23: 0.17213841 | CZ23: 0.44770534 | DA23: 0.025018511 | DB23: 0.018747066 | DC23: 0.11415247 | DD23: 0.092798675 | DE23: -0.060085948 | DF23: 0.40879492 | DG23: 0.029625501 | DH23: 0.13922689 | DI23: 0.092924309 | DJ23: 0.057281999 | DK23: 0.063146578 | DL23: 0.054101277 | DM23: -0.033366756 | DN23: 0.17592581 | DO23: -0.049077327 | DP23: 0.17431301 | DQ23: 0.28304274 | DR23: -0.060496157 | DS23: -0.11657599 | DT23: 0.083862877 | DU23: 0.055639479 | DV23: 0.52435736 | DW23: 0.023051821 | DX23: 0.10460565 | DY23: 0.35963099 | DZ23: 0.060555375 | EA23: -0.096958321 | EB23: 0.33153538 | EC23: 0.016845937 | ED23: 0.11627237 | EE23: 0.027630933 | EF23: 0.090054994 | EG23: 1.286951 | EH23: -0.18195095 | EI23: 0.014102849 | EJ23: -0.069451151 | EK23: 0.12396271 | EL23: 0.037867477 | EM23: =AVERAGE(C23:EL23) -> 0.098955744 | EN23: =STDEV(C23:EL23) -> 0.1945888 | EO23: =EM23/EN23 -> 0.50853771
A24: 1051 | B24: =ROUND($D$10/A24,0) -> 1 | C24: 0.099113364 | D24: 0.10060991 | E24: 0.2845125 | F24: -0.075326494 | G24: -0.022622389 | H24: 0.035855797 | I24: -0.0021119332 | J24: -0.054302156 | K24: 0.053732997 | L24: -0.093799693 | M24: -0.14681934 | N24: 1.7690314 | O24: 0.036648791 | P24: 0.10424841 | Q24: 0.090144949 | R24: -0.24569737 | S24: 0.1008088 | T24: -0.077938396 | U24: -0.28585629 | V24: -0.15982629 | W24: -0.16456452 | X24: -0.036157896 | Y24: -0.0094770149 | Z24: 0.11139618 | AA24: 0.28502017 | AB24: 0.19533962 | AC24: -0.00042768817 | AD24: 0.1011753 | AE24: 0.11173128 | AF24: 0.074833925 | AG24: 0.13313425 | AH24: -0.05669736 | AI24: 0.21453722 | AJ24: -0.080891244 | AK24: 0.084883953 | AL24: 0.087173701 | AM24: -0.018919281 | AN24: 0.22118947 | AO24: 0.1029057 | AP24: 0.022851715 | AQ24: -0.29800338 | AR24: 0.17083341 | AS24: -0.059514128 | AT24: 0.15076898 | AU24: 0.47705419 | AV24: 0.24768466 | AW24: 0.12663114 | AX24: 0.11149134 | AY24: 0.16812729 | AZ24: 0.11862373 | BA24: 0.050491305 | BB24: 0.87270315 | BC24: -0.80321601 | BD24: 0.018631034 | BE24: -0.057380538 | BF24: -0.064370421 | BG24: -0.090984228 | BH24: 0.14767357 | BI24: 0.14021393 | BJ24: -0.10732902 | BK24: -0.034827647 | BL24: 0.10610692 | BM24: 0.08478294 | BN24: 0.10891326 | BO24: -0.16110969 | BP24: 0.031794104 | BQ24: -0.064169633 | BR24: 0.098920889 | BS24: -0.14032011 | BT24: 0.27671902 | BU24: 0.0087484923 | BV24: -0.046258706 | BW24: 0.15699245 | BX24: -0.23222627 | BY24: 0.29033687 | BZ24: -0.20258079 | CA24: 0.10875309 | CB24: 0.052917307 | CC24: -0.21983119 | CD24: 0.2390466 | CE24: -0.055004727 | CF24: 0.11681539 | CG24: 0.64058463 | CH24: -0.10127493 | CI24: 0.12117759 | CJ24: -0.4374308 | CK24: -0.008787376 | CL24: 0.65620131 | CM24: 0.0027194555 | CN24: 0.60755967 | CO24: 0.08735443 | CP24: 0.12929403 | CQ24: 0.1309272 | CR24: 0.02212628 | CS24: 0.15934836 | CT24: 0.38294619 | CU24: 0.052729045 | CV24: 0.26202484 | CW24: -0.29572306 | CX24: 0.14693642 | CY24: 0.36022805 | CZ24: 0.34631321 | DA24: 0.033979585 | DB24: -0.016501866 | DC24: 0.1944536 | DD24: -0.19584472 | DE24: 0.13158559 | DF24: 0.52558501 | DG24: 0.11954529 | DH24: 0.26580268 | DI24: 0.14201474 | DJ24: 0.021081471 | DK24: 0.06348336 | DL24: 0.047769086 | DM24: 0.025807675 | DN24: 0.13696045 | DO24: -0.040894289 | DP24: 0.33563188 | DQ24: 0.3470111 | DR24: -0.046637311 | DS24: -0.067362546 | DT24: 0.0056640306 | DU24: -0.021781395 | DV24: 0.65439619 | DW24: 0.1011825 | DX24: -0.10618198 | DY24: 0.34380429 | DZ24: 0.050469182 | EA24: -0.027229621 | EB24: 0.68520167 | EC24: 0.013684175 | ED24: 0.1147491 | EE24: 0.10748066 | EF24: 0.13408708 | EG24: 2.3153613 | EH24: -0.38423032 | EI24: 0.11174428 | EJ24: -0.085941736 | EK24: 0.13991261 | EL24: 0.065077029 | EM24: =AVERAGE(C24:EL24) -> 0.10171619 | EN24: =STDEV(C24:EL24) -> 0.32087857 | EO24: =EM24/EN24 -> 0.31699279
A25: 大盤 | B25: TWII | C25: -0.017446771 | D25: 0.020701061 | E25: 0.023982129 | F25: -0.006557579 | G25: 0.03184513 | H25: 0.034348533 | I25: -0.0082549328 | J25: 0.012843524 | K25: -0.051018525 | L25: 0.00087394274 | M25: 0.023389576 | N25: 0.012988972 | O25: 0.0058545887 | P25: 0.027413207 | Q25: -0.0037129361 | R25: 0.024076614 | S25: -0.012190025 | T25: -0.039749578 | U25: -0.07315545 | V25: -0.05826023 | W25: 0.00077279757 | X25: 0.044591521 | Y25: -0.02769968 | Z25: 0.0020950059 | AA25: -0.023400551 | AB25: 0.032129371 | AC25: 0.038903273 | AD25: -0.042865382 | AE25: 0.018647195 | AF25: 0.015229768 | AG25: 0.036016604 | AH25: 0.0093546114 | AI25: 0.010748251 | AJ25: 0.013357754 | AK25: -0.0053327473 | AL25: 0.0013831358 | AM25: 0.020795928 | AN25: 0.031517702 | AO25: 0.0062417165 | AP25: 0.0061452617 | AQ25: 0.016946358 | AR25: 0.03468283 | AS25: 0.0030985886 | AT25: 0.015081347 | AU25: -0.019251209 | AV25: 0.038711513 | AW25: -0.021856951 | AX25: 0.0077743007 | AY25: 0.042397247 | AZ25: -0.026308975 | BA25: 0.0095717493 | BB25: -0.024249741 | BC25: 0.020163374 | BD25: -0.0035049988 | BE25: 0.020151935 | BF25: 0.00058133623 | BG25: -0.005219701 | BH25: -0.11587176 | BI25: 0.0087252257 | BJ25: -0.016377261 | BK25: 0.020840372 | BL25: 0.044975872 | BM25: 0.023954306 | BN25: 0.030239101 | BO25: -0.043725888 | BP25: 0.02188947 | BQ25: 0.0086274303 | BR25: -0.019192954 | BS25: 0.01973513 | BT25: 0.047694337 | BU25: 0.011454817 | BV25: 0.043228621 | BW25: -0.04274743 | BX25: -0.017811292 | BY25: -0.1511531 | BZ25: 0.124224 | CA25: -0.0045572538 | CB25: 0.06021124 | CC25: 0.085992033 | CD25: -0.0058084796 | CE25: -0.006041347 | CF25: 0.0024523244 | CG25: 0.089636252 | CH25: 0.070992733 | CI25: 0.027170643 | CJ25: 0.052468428 | CK25: 0.029480661 | CL25: 0.066825081 | CM25: -0.028772229 | CN25: 0.039462516 | CO25: -0.029031087 | CP25: 0.013983883 | CQ25: -0.032276965 | CR25: 0.0031035766 | CS25: 0.025591856 | CT25: 0.044391886 | CU25: -0.030338959 | CV25: -0.0012579765 | CW25: 0.0023363565 | CX25: -0.064264145 | CY25: 0.012909779 | CZ25: -0.12547709 | DA25: 0.011690683 | DB25: 0.0063378437 | DC25: -0.11730536 | DD25: -0.036010872 | DE25: 0.1389113 | DF25: -0.051143506 | DG25: 0.076731447 | DH25: 0.015508782 | DI25: 0.023223774 | DJ25: -0.018372876 | DK25: 0.062199014 | DL25: 0.020098304 | DM25: 0.01349894 | DN25: -0.030252213 | DO25: -0.017022836 | DP25: -0.021788523 | DQ25: 0.085745625 | DR25: 0.028106744 | DS25: -0.0023031598 | DT25: 0.058471198 | DU25: 0.067658949 | DV25: 0.0050207706 | DW25: 0.037416184 | DX25: 0.084111004 | DY25: -0.036832399 | DZ25: 0.0030917028 | EA25: -0.0019576282 | EB25: 0.026459104 | EC25: -0.024752539 | ED25: 0.034115491 | EE25: 0.021061974 | EF25: -0.020277393 | EG25: -0.10786811 | EH25: -0.022520352 | EI25: 0.053510007 | EJ25: 0.041687266 | EK25: 0.056195614 | EL25: 0.028911319 | EM25: =AVERAGE(C25:EL25) -> 0.0073901413 | EN25: =STDEV(C25:EL25) -> 0.043085791 | EO25: =EM25/EN25 -> 0.17152154

Sheet 預測IC
A1: Predict
B2: Time | C2: 2013/12 | D2: 2014/01 | E2: 2014/02 | F2: 2014/03 | G2: 2014/04 | H2: 2014/05 | I2: 2014/06 | J2: 2014/07 | K2: 2014/08 | L2: 2014/09 | M2: 2014/10 | N2: 2014/11 | O2: 2014/12 | P2: 2015/01 | Q2: 2015/02 | R2: 2015/03 | S2: 2015/04 | T2: 2015/05 | U2: 2015/06 | V2: 2015/07 | W2: 2015/08 | X2: 2015/09 | Y2: 2015/10 | Z2: 2015/11 | AA2: 2015/12 | AB2: 2016/01 | AC2: 2016/02 | AD2: 2016/03 | AE2: 2016/04 | AF2: 2016/05 | AG2: 2016/06 | AH2: 2016/07 | AI2: 2016/08 | AJ2: 2016/09 | AK2: 2016/10 | AL2: 2016/11 | AM2: 2016/12 | AN2: 2017/01 | AO2: 2017/02 | AP2: 2017/03 | AQ2: 2017/04 | AR2: 2017/05 | AS2: 2017/06 | AT2: 2017/07 | AU2: 2017/08 | AV2: 2017/09 | AW2: 2017/10 | AX2: 2017/11 | AY2: 2017/12 | AZ2: 2018/01 | BA2: 2018/02 | BB2: 2018/03 | BC2: 2018/04 | BD2: 2018/05 | BE2: 2018/06 | BF2: 2018/07 | BG2: 2018/08 | BH2: 2018/09 | BI2: 2018/10 | BJ2: 2018/11 | BK2: 2018/12 | BL2: 2019/01 | BM2: 2019/02 | BN2: 2019/03 | BO2: 2019/04 | BP2: 2019/05 | BQ2: 2019/06 | BR2: 2019/07 | BS2: 2019/08 | BT2: 2019/09 | BU2: 2019/10 | BV2: 2019/11 | BW2: 2019/12 | BX2: 2020/01 | BY2: 2020/02 | BZ2: 2020/03 | CA2: 2020/04 | CB2: 2020/05 | CC2: 2020/06 | CD2: 2020/07 | CE2: 2020/08 | CF2: 2020/09 | CG2: 2020/10 | CH2: 2020/11 | CI2: 2020/12 | CJ2: 2021/01 | CK2: 2021/02 | CL2: 2021/03 | CM2: 2021/04 | CN2: 2021/05 | CO2: 2021/06 | CP2: 2021/07 | CQ2: 2021/08 | CR2: 2021/09 | CS2: 2021/10 | CT2: 2021/11 | CU2: 2021/12 | CV2: 2022/01 | CW2: 2022/02 | CX2: 2022/03 | CY2: 2022/04 | CZ2: 2022/05 | DA2: 2022/06 | DB2: 2022/07 | DC2: 2022/08 | DD2: 2022/09 | DE2: 2022/10 | DF2: 2022/11 | DG2: 2022/12 | DH2: 2023/01 | DI2: 2023/02 | DJ2: 2023/03 | DK2: 2023/04 | DL2: 2023/05 | DM2: 2023/06 | DN2: 2023/07 | DO2: 2023/08 | DP2: 2023/09 | DQ2: 2023/10 | DR2: 2023/11 | DS2: 2023/12 | DT2: 2024/01 | DU2: 2024/02 | DV2: 2024/03 | DW2: 2024/04 | DX2: 2024/05 | DY2: 2024/06 | DZ2: 2024/07 | EA2: 2024/08 | EB2: 2024/09 | EC2: 2024/10 | ED2: 2024/11 | EE2: 2024/12 | EF2: 2025/01 | EG2: 2025/02 | EH2: 2025/03 | EI2: 2025/04 | EJ2: 2025/05 | EK2: 2025/06 | EL2: 2025/07 | EM2: 2025/08
B3: bm | C3: 0.014921768 | D3: 0.19374056 | E3: 0.036641285 | F3: 0.027200378 | G3: 0.04157251 | H3: -0.037682778 | I3: -0.14193848 | J3: 0.22945654 | K3: 0.043442237 | L3: 0.020280323 | M3: 0.058836121 | N3: -0.15172078 | O3: 0.32674605 | P3: 0.15440774 | Q3: -0.10779532 | R3: -0.073882179 | S3: 0.053466578 | T3: -0.055190803 | U3: -0.25838402 | V3: 0.018370553 | W3: 0.22943516 | X3: -0.17107395 | Y3: 0.22961919 | Z3: 0.016609176 | AA3: 0.42374789 | AB3: -0.21459678 | AC3: 0.044537468 | AD3: 0.1026364 | AE3: -0.0508277 | AF3: -0.089107468 | AG3: 0.12223872 | AH3: -0.11260452 | AI3: 0.13141393 | AJ3: 0.16749207 | AK3: 0.090663365 | AL3: 0.19313854 | AM3: 0.077111194 | AN3: 0.25612014 | AO3: 0.049003918 | AP3: 0.040886892 | AQ3: -0.11058243 | AR3: 0.022954756 | AS3: 0.048656704 | AT3: -0.054229837 | AU3: 0.08631682 | AV3: 0.039564967 | AW3: -0.19104491 | AX3: 0.09710944 | AY3: -0.019067526 | AZ3: -0.09116936 | BA3: 0.16595814 | BB3: -0.041157026 | BC3: 0.13020995 | BD3: 0.20026039 | BE3: -0.10617652 | BF3: 0.0039767283 | BG3: 0.33032254 | BH3: 0.31722693 | BI3: 0.015898229 | BJ3: 0.085118054 | BK3: 0.085442583 | BL3: 0.060053602 | BM3: 0.077486633 | BN3: 0.061035782 | BO3: -0.21386733 | BP3: 0.18539731 | BQ3: -0.054154026 | BR3: 0.28168982 | BS3: -0.023481657 | BT3: 0.089034675 | BU3: 0.12734099 | BV3: 0.019220334 | BW3: 0.06654711 | BX3: -0.10968389 | BY3: 0.13853337 | BZ3: -0.10485789 | CA3: -0.050171625 | CB3: -0.070239616 | CC3: -0.0060243315 | CD3: 0.15997201 | CE3: 0.21131662 | CF3: -0.10098227 | CG3: 0.10999023 | CH3: -0.014392635 | CI3: 0.22258294 | CJ3: -0.28268221 | CK3: -0.013478474 | CL3: -0.077844883 | CM3: 0.27379286 | CN3: -0.39000662 | CO3: -0.15858239 | CP3: -0.022486871 | CQ3: 0.15587954 | CR3: 0.081444486 | CS3: -0.074204537 | CT3: -0.09237128 | CU3: -0.04371403 | CV3: 0.029888249 | CW3: 0.089064661 | CX3: -0.024617034 | CY3: 0.070863408 | CZ3: 0.040860065 | DA3: 0.25668575 | DB3: -0.16423593 | DC3: -0.25891871 | DD3: -0.031636235 | DE3: 0.16039046 | DF3: -0.11251514 | DG3: -0.082270484 | DH3: -0.1046574 | DI3: 0.048360524 | DJ3: -0.057256595 | DK3: 0.044306651 | DL3: -0.01550485 | DM3: -0.11873725 | DN3: -0.022084537 | DO3: -0.093328814 | DP3: 0.16589996 | DQ3: 0.19277347 | DR3: -0.053222765 | DS3: 0.12855034 | DT3: -0.12713794 | DU3: -0.12167815 | DV3: -0.073321393 | DW3: 0.057692105 | DX3: 0.090231456 | DY3: -0.13571093 | DZ3: 0.20883876 | EA3: -0.10421373 | EB3: 0.19552286 | EC3: -0.083944739 | ED3: -0.041132651 | EE3: -0.11014068 | EF3: -0.037066133 | EG3: 0.080655585 | EH3: 0.17418837 | EI3: 0.10188061 | EJ3: -0.079899408 | EK3: -0.14702487 | EL3: -0.16515914 | EM3: -0.19545451
