Workbook

Sheet 真實IC
A1: Real
B2: Time | C2: 2013/12 | D2: 2014/01 | E2: 2014/02 | F2: 2014/03 | G2: 2014/04 | H2: 2014/05 | I2: 2014/06 | J2: 2014/07 | K2: 2014/08 | L2: 2014/09 | M2: 2014/10 | N2: 2014/11 | O2: 2014/12 | P2: 2015/01 | Q2: 2015/02 | R2: 2015/03 | S2: 2015/04 | T2: 2015/05 | U2: 2015/06 | V2: 2015/07 | W2: 2015/08 | X2: 2015/09 | Y2: 2015/10 | Z2: 2015/11 | AA2: 2015/12 | AB2: 2016/01 | AC2: 2016/02 | AD2: 2016/03 | AE2: 2016/04 | AF2: 2016/05 | AG2: 2016/06 | AH2: 2016/07 | AI2: 2016/08 | AJ2: 2016/09 | AK2: 2016/10 | AL2: 2016/11 | AM2: 2016/12 | AN2: 2017/01 | AO2: 2017/02 | AP2: 2017/03 | AQ2: 2017/04 | AR2: 2017/05 | AS2: 2017/06 | AT2: 2017/07 | AU2: 2017/08 | AV2: 2017/09 | AW2: 2017/10 | AX2: 2017/11 | AY2: 2017/12 | AZ2: 2018/01 | BA2: 2018/02 | BB2: 2018/03 | BC2: 2018/04 | BD2: 2018/05 | BE2: 2018/06 | BF2: 2018/07 | BG2: 2018/08 | BH2: 2018/09 | BI2: 2018/10 | BJ2: 2018/11 | BK2: 2018/12 | BL2: 2019/01 | BM2: 2019/02 | BN2: 2019/03 | BO2: 2019/04 | BP2: 2019/05 | BQ2: 2019/06 | BR2: 2019/07 | BS2: 2019/08 | BT2: 2019/09 | BU2: 2019/10 | BV2: 2019/11 | BW2: 2019/12 | BX2: 2020/01 | BY2: 2020/02 | BZ2: 2020/03 | CA2: 2020/04 | CB2: 2020/05 | CC2: 2020/06 | CD2: 2020/07 | CE2: 2020/08 | CF2: 2020/09 | CG2: 2020/10 | CH2: 2020/11 | CI2: 2020/12 | CJ2: 2021/01 | CK2: 2021/02 | CL2: 2021/03 | CM2: 2021/04 | CN2: 2021/05 | CO2: 2021/06 | CP2: 2021/07 | CQ2: 2021/08 | CR2: 2021/09 | CS2: 2021/10 | CT2: 2021/11 | CU2: 2021/12 | CV2: 2022/01 | CW2: 2022/02 | CX2: 2022/03 | CY2: 2022/04 | CZ2: 2022/05 | DA2: 2022/06 | DB2: 2022/07 | DC2: 2022/08 | DD2: 2022/09 | DE2: 2022/10 | DF2: 2022/11 | DG2: 2022/12 | DH2: 2023/01 | DI2: 2023/02 | DJ2: 2023/03 | DK2: 2023/04 | DL2: 2023/05 | DM2: 2023/06 | DN2: 2023/07 | DO2: 2023/08 | DP2: 2023/09 | DQ2: 2023/10 | DR2: 2023/11 | DS2: 2023/12 | DT2: 2024/01 | DU2: 2024/02 | DV2: 2024/03 | DW2: 2024/04 | DX2: 2024/05 | DY2: 2024/06 | DZ2: 2024/07 | EA2: 2024/08 | EB2: 2024/09 | EC2: 2024/10 | ED2: 2024/11 | EE2: 2024/12 | EF2: 2025/01 | EG2: 2025/02 | EH2: 2025/03 | EI2: 2025/04 | EJ2: 2025/05 | EK2: 2025/06 | EL2: 2025/07 | EM2: 2025/08
B3: bm | C3: 0.11254353 | D3: 0.034097093 | E3: -0.034092261 | F3: -0.016058652 | G3: -0.0032385096 | H3: 0.037901102 | I3: 0.19658042 | J3: 0.123748 | K3: -0.0034480581 | L3: 0.056295168 | M3: -0.033270601 | N3: 0.13532466 | O3: 0.02969531 | P3: -0.075919536 | Q3: -0.062747606 | R3: 0.034334773 | S3: -0.11448918 | T3: -0.128411 | U3: -0.01815403 | V3: 0.097284226 | W3: 0.06448606 | X3: 0.1327038 | Y3: -0.14506291 | Z3: 0.15983802 | AA3: -0.079439674 | AB3: 0.065463771 | AC3: 0.10841757 | AD3: 0.035162094 | AE3: -0.13259397 | AF3: 0.079167282 | AG3: 0.1474472 | AH3: 0.10818108 | AI3: 0.031505046 | AJ3: 0.068324574 | AK3: 0.13938042 | AL3: 0.0015927447 | AM3: 0.11699323 | AN3: 0.18348806 | AO3: -0.013624633 | AP3: -0.10636754 | AQ3: -0.026929215 | AR3: 0.042036531 | AS3: 0.018696587 | AT3: 0.050640506 | AU3: 0.060413159 | AV3: -0.049074617 | AW3: 0.041357509 | AX3: 0.1327231 | AY3: 0.05462578 | AZ3: 0.015696796 | BA3: 0.012690345 | BB3: 0.10435302 | BC3: 0.027796633 | BD3: 0.015784322 | BE3: 0.053739938 | BF3: 0.15375844 | BG3: 0.14726982 | BH3: 0.058771535 | BI3: 0.089685564 | BJ3: -0.041235808 | BK3: -0.085734728 | BL3: 0.06541404 | BM3: -0.031368353 | BN3: 0.035359622 | BO3: 0.077704285 | BP3: -0.014539108 | BQ3: 0.054478665 | BR3: -0.011979953 | BS3: 0.061686425 | BT3: 0.017609737 | BU3: 0.001762998 | BV3: 0.079901428 | BW3: -0.026106377 | BX3: 0.022152374 | BY3: -0.070677725 | BZ3: 0.10127162 | CA3: -0.11166328 | CB3: 0.021342222 | CC3: -0.0047361279 | CD3: 0.17955101 | CE3: 0.061307643 | CF3: 0.091604774 | CG3: 0.097692005 | CH3: 0.15714712 | CI3: -0.088647186 | CJ3: -0.014935576 | CK3: 0.038208336 | CL3: 0.31725854 | CM3: -0.04994997 | CN3: -0.038447027 | CO3: 0.00071081192 | CP3: 0.14471258 | CQ3: 0.14928899 | CR3: -0.039801054 | CS3: -0.046545919 | CT3: 0.034133664 | CU3: 0.12875406 | CV3: 0.031635368 | CW3: 0.041194563 | CX3: 0.16319544 | CY3: -0.043115028 | CZ3: 0.22006844 | DA3: -0.04142373 | DB3: -0.011737974 | DC3: 0.10777107 | DD3: 0.067224014 | DE3: -0.040137128 | DF3: 0.036396903 | DG3: -0.098061051 | DH3: -0.012045848 | DI3: -0.089410575 | DJ3: 0.054992879 | DK3: -0.057186589 | DL3: -0.029284301 | DM3: -0.031402929 | DN3: 0.084413623 | DO3: 0.048170818 | DP3: 0.090346423 | DQ3: -0.11867639 | DR3: 0.11050757 | DS3: -0.073814619 | DT3: -0.10633883 | DU3: 0.0096230219 | DV3: 0.14417122 | DW3: 0.085312212 | DX3: -0.11038018 | DY3: 0.12870772 | DZ3: -0.053270106 | EA3: 0.17325686 | EB3: 0.012264442 | EC3: 0.077320493 | ED3: -0.16510374 | EE3: 0.077592443 | EF3: 0.056688315 | EG3: 0.1757144 | EH3: -0.050736759 | EI3: -0.032979675 | EJ3: -0.1750733 | EK3: 0.075703333 | EL3: -0.11145874 | EM3: #NUM!
B4: size | C4: -0.26567505 | D4: -0.26274582 | E4: -0.078695496 | F4: 0.065706805 | G4: -0.059999729 | H4: -0.090782629 | I4: -0.029543457 | J4: 0.06875609 | K4: -0.045430805 | L4: 0.092349485 | M4: 0.0055332373 | N4: -0.20262956 | O4: -0.055439189 | P4: 0.063019438 | Q4: -0.051127471 | R4: -0.0026369264 | S4: 0.11737044 | T4: 0.028121058 | U4: 0.024399698 | V4: 0.0024693189 | W4: -0.12931199 | X4: -0.078183592 | Y4: -0.016789063 | Z4: -0.021755872 | AA4: 0.056064772 | AB4: -0.026152478 | AC4: -0.070545451 | AD4: -0.046059359 | AE4: 0.13302405 | AF4: -0.089277754 | AG4: -0.059320758 | AH4: -0.055248054 | AI4: -0.03443289 | AJ4: -0.0010118202 | AK4: 0.010080194 | AL4: -0.11988371 | AM4: -0.0052132143 | AN4: -0.10834391 | AO4: -0.058361176 | AP4: 0.010829655 | AQ4: 0.0091678033 | AR4: 0.094714182 | AS4: -0.024402385 | AT4: 0.0020132029 | AU4: -0.16715058 | AV4: 0.033972262 | AW4: -0.016836938 | AX4: -0.034706448 | AY4: 0.0051832253 | AZ4: -0.11973657 | BA4: -0.13521273 | BB4: 0.016982 | BC4: 0.023074368 | BD4: -0.11999454 | BE4: 0.12932848 | BF4: 0.016709915 | BG4: -0.022306747 | BH4: 0.039303081 | BI4: -0.10048888 | BJ4: -0.10199028 | BK4: 0.099875651 | BL4: -0.032934037 | BM4: 0.0262875 | BN4: 0.10734549 | BO4: -0.025606337 | BP4: 0.12241177 | BQ4: -0.045440179 | BR4: -0.071268977 | BS4: -0.068098859 | BT4: 0.092203282 | BU4: 0.082899618 | BV4: -0.041301127 | BW4: -0.099351182 | BX4: -0.038144887 | BY4: 0.11248742 | BZ4: -0.037880283 | CA4: -0.091542003 | CB4: -0.12463256 | CC4: -0.061699946 | CD4: -0.075868372 | CE4: -0.22128938 | CF4: 0.0086756078 | CG4: 0.031786264 | CH4: -0.037814116 | CI4: 0.049549068 | CJ4: -0.010429677 | CK4: -0.083344347 | CL4: -0.053422112 | CM4: 0.19037761 | CN4: 0.058217829 | CO4: -0.14266652 | CP4: 0.041776779 | CQ4: -0.16944775 | CR4: -0.084810245 | CS4: -0.03477087 | CT4: -0.11929695 | CU4: -0.017795179 | CV4: -0.014834128 | CW4: -0.046319066 | CX4: -0.09663469 | CY4: -0.078834385 | CZ4: -0.21252635 | DA4: -0.11368552 | DB4: -0.1831019 | DC4: -0.042499865 | DD4: 0.027817596 | DE4: 0.068607937 | DF4: -0.13309486 | DG4: 0.22249787 | DH4: -0.13075878 | DI4: -0.10969183 | DJ4: -0.11047372 | DK4: 0.085555392 | DL4: -0.037902764 | DM4: 0.083550635 | DN4: -0.055064654 | DO4: -0.091404376 | DP4: -0.14635791 | DQ4: 0.07258441 | DR4: -0.036982983 | DS4: -0.15848873 | DT4: -0.076734871 | DU4: 0.1465233 | DV4: 0.0092142529 | DW4: -0.12809453 | DX4: -0.057788778 | DY4: -0.10353071 | DZ4: -0.053247234 | EA4: -0.11101122 | EB4: -0.057337042 | EC4: 0.053167127 | ED4: 0.055871006 | EE4: 0.15335804 | EF4: -0.11423136 | EG4: -0.044005617 | EH4: 0.017544152 | EI4: 0.086430773 | EJ4: 0.13519055 | EK4: 0.12749822 | EL4: -0.030403121 | EM4: #NUM!
B5: mom | C5: -0.024114963 | D5: 0.1401006 | E5: -0.0054828677 | F5: -0.04806796 | G5: 0.098556491 | H5: 0.0040265399 | I5: -0.054392917 | J5: -0.00078467923 | K5: 0.03198565 | L5: -0.0052053083 | M5: 0.083785175 | N5: -0.056914478 | O5: 0.06851042 | P5: 0.028609346 | Q5: 0.066853829 | R5: -0.0022018586 | S5: 0.13430089 | T5: 0.13091808 | U5: 0.013133991 | V5: 0.026183164 | W5: -0.094297429 | X5: -0.30132339 | Y5: 0.10842895 | Z5: -0.14174493 | AA5: 0.11702124 | AB5: -0.022180044 | AC5: -0.086460961 | AD5: 0.021464874 | AE5: 0.15421824 | AF5: -0.14648945 | AG5: -0.047015552 | AH5: 0.019690199 | AI5: 0.039309116 | AJ5: -0.026623525 | AK5: -0.025125102 | AL5: -0.10344397 | AM5: 0.06190072 | AN5: 0.076731055 | AO5: 0.098982723 | AP5: 0.054076693 | AQ5: -0.030251892 | AR5: 0.00044910599 | AS5: 0.070194262 | AT5: 0.17429282 | AU5: -0.081385666 | AV5: 0.15075612 | AW5: 0.057401718 | AX5: -0.15692285 | AY5: 0.047095412 | AZ5: -0.057117988 | BA5: -0.022411435 | BB5: -0.15274623 | BC5: 0.022968193 | BD5: 0.0010412666 | BE5: -0.13310703 | BF5: -0.19610968 | BG5: -0.18881309 | BH5: -0.10071704 | BI5: -0.12578122 | BJ5: -0.010946697 | BK5: -0.061548923 | BL5: -0.15045858 | BM5: 0.12760274 | BN5: -0.017866803 | BO5: -0.025323955 | BP5: 0.040051232 | BQ5: -0.042262606 | BR5: 0.17888215 | BS5: -0.099129045 | BT5: 0.040560012 | BU5: 0.063241856 | BV5: -0.096181909 | BW5: -0.13606285 | BX5: -0.0050219314 | BY5: 0.11233989 | BZ5: 0.034223088 | CA5: 0.070051209 | CB5: 0.023662883 | CC5: 0.093938184 | CD5: -0.029913967 | CE5: -0.10685236 | CF5: -0.058583352 | CG5: -0.1185641 | CH5: -0.047815465 | CI5: -0.061561116 | CJ5: 0.22741941 | CK5: 0.1332388 | CL5: 0.040261514 | CM5: -0.073899374 | CN5: 0.24689459 | CO5: -0.10444084 | CP5: -0.017008494 | CQ5: -0.20843471 | CR5: -0.083953984 | CS5: 0.08662128 | CT5: -0.02628501 | CU5: -0.29981484 | CV5: 0.24030007 | CW5: 0.09157936 | CX5: -0.099166296 | CY5: 0.10766172 | CZ5: -0.054245194 | DA5: 0.08253219 | DB5: 0.13651007 | DC5: -0.013925396 | DD5: -0.13979564 | DE5: -0.09411437 | DF5: 0.052829966 | DG5: -0.19928626 | DH5: 0.10213914 | DI5: 0.037772798 | DJ5: 0.065447994 | DK5: 0.059654622 | DL5: 0.095335574 | DM5: 0.040485912 | DN5: 0.0034939953 | DO5: -0.10610844 | DP5: -0.24479189 | DQ5: 0.21383696 | DR5: 0.010889666 | DS5: 0.13411936 | DT5: 0.12417191 | DU5: 0.078095889 | DV5: -0.053915428 | DW5: -0.023828252 | DX5: 0.066514734 | DY5: 0.019361307 | DZ5: 0.018750008 | EA5: -0.28354334 | EB5: -0.13389241 | EC5: -0.022714427 | ED5: 0.044607042 | EE5: -0.129061 | EF5: -0.065742552 | EG5: -0.11722283 | EH5: -0.026547499 | EI5: -0.033015556 | EJ5: 0.045977173 | EK5: -0.069235534 | EL5: 0.014684336 | EM5: #NUM!
A6: 絕對值最大 | C6: {=MATCH(MAX(ABS(C3:C5)), ABS(C3:C5), 0)} | D6: {=MATCH(MAX(ABS(D3:D5)), ABS(D3:D5), 0)} | E6: {=MATCH(MAX(ABS(E3:E5)), ABS(E3:E5), 0)} | F6: {=MATCH(MAX(ABS(F3:F5)), ABS(F3:F5), 0)} | G6: {=MATCH(MAX(ABS(G3:G5)), ABS(G3:G5), 0)} | H6: {=MATCH(MAX(ABS(H3:H5)), ABS(H3:H5), 0)} | I6: {=MATCH(MAX(ABS(I3:I5)), ABS(I3:I5), 0)} | J6: {=MATCH(MAX(ABS(J3:J5)), ABS(J3:J5), 0)} | ... EM6: {=MATCH(MAX(ABS(EM3:EM5)), ABS(EM3:EM5), 0)}
C7: =IF(C6=1,"bm",IF(C6=2,"size",IF(C6=3,"mom"))) | D7: =IF(D6=1,"bm",IF(D6=2,"size",IF(D6=3,"mom"))) | E7: =IF(E6=1,"bm",IF(E6=2,"size",IF(E6=3,"mom"))) | F7: =IF(F6=1,"bm",IF(F6=2,"size",IF(F6=3,"mom"))) | G7: =IF(G6=1,"bm",IF(G6=2,"size",IF(G6=3,"mom"))) | H7: =IF(H6=1,"bm",IF(H6=2,"size",IF(H6=3,"mom"))) | I7: =IF(I6=1,"bm",IF(I6=2,"size",IF(I6=3,"mom"))) | J7: =IF(J6=1,"bm",IF(J6=2,"size",IF(J6=3,"mom"))) | ... EM7: =IF(EM6=1,"bm",IF(EM6=2,"size",IF(EM6=3,"mom")))
C8: =IF(C6=1,C3,IF(C6=2,C4,IF(C6=3,C5))) | D8: =IF(D6=1,D3,IF(D6=2,D4,IF(D6=3,D5))) | E8: =IF(E6=1,E3,IF(E6=2,E4,IF(E6=3,E5))) | F8: =IF(F6=1,F3,IF(F6=2,F4,IF(F6=3,F5))) | G8: =IF(G6=1,G3,IF(G6=2,G4,IF(G6=3,G5))) | H8: =IF(H6=1,H3,IF(H6=2,H4,IF(H6=3,H5))) | I8: =IF(I6=1,I3,IF(I6=2,I4,IF(I6=3,I5))) | J8: =IF(J6=1,J3,IF(J6=2,J4,IF(J6=3,J5))) | ... EM8: =IF(EM6=1,EM3,IF(EM6=2,EM4,IF(EM6=3,EM5)))
A10: 投資組合 | C10: 公司數 | D10: 1051
A11: 等分 | B11: 家數 | C11: 2013/12 | D11: 2014/01 | E11: 2014/02 | F11: 2014/03 | G11: 2014/04 | H11: 2014/05 | I11: 2014/06 | J11: 2014/07 | K11: 2014/08 | L11: 2014/09 | M11: 2014/10 | N11: 2014/11 | O11: 2014/12 | P11: 2015/01 | Q11: 2015/02 | R11: 2015/03 | S11: 2015/04 | T11: 2015/05 | U11: 2015/06 | V11: 2015/07 | W11: 2015/08 | X11: 2015/09 | Y11: 2015/10 | Z11: 2015/11 | AA11: 2015/12 | AB11: 2016/01 | AC11: 2016/02 | AD11: 2016/03 | AE11: 2016/04 | AF11: 2016/05 | AG11: 2016/06 | AH11: 2016/07 | AI11: 2016/08 | AJ11: 2016/09 | AK11: 2016/10 | AL11: 2016/11 | AM11: 2016/12 | AN11: 2017/01 | AO11: 2017/02 | AP11: 2017/03 | AQ11: 2017/04 | AR11: 2017/05 | AS11: 2017/06 | AT11: 2017/07 | AU11: 2017/08 | AV11: 2017/09 | AW11: 2017/10 | AX11: 2017/11 | AY11: 2017/12 | AZ11: 2018/01 | BA11: 2018/02 | BB11: 2018/03 | BC11: 2018/04 | BD11: 2018/05 | BE11: 2018/06 | BF11: 2018/07 | BG11: 2018/08 | BH11: 2018/09 | BI11: 2018/10 | BJ11: 2018/11 | BK11: 2018/12 | BL11: 2019/01 | BM11: 2019/02 | BN11: 2019/03 | BO11: 2019/04 | BP11: 2019/05 | BQ11: 2019/06 | BR11: 2019/07 | BS11: 2019/08 | BT11: 2019/09 | BU11: 2019/10 | BV11: 2019/11 | BW11: 2019/12 | BX11: 2020/01 | BY11: 2020/02 | BZ11: 2020/03 | CA11: 2020/04 | CB11: 2020/05 | CC11: 2020/06 | CD11: 2020/07 | CE11: 2020/08 | CF11: 2020/09 | CG11: 2020/10 | CH11: 2020/11 | CI11: 2020/12 | CJ11: 2021/01 | CK11: 2021/02 | CL11: 2021/03 | CM11: 2021/04 | CN11: 2021/05 | CO11: 2021/06 | CP11: 2021/07 | CQ11: 2021/08 | CR11: 2021/09 | CS11: 2021/10 | CT11: 2021/11 | CU11: 2021/12 | CV11: 2022/01 | CW11: 2022/02 | CX11: 2022/03 | CY11: 2022/04 | CZ11: 2022/05 | DA11: 2022/06 | DB11: 2022/07 | DC11: 2022/08 | DD11: 2022/09 | DE11: 2022/10 | DF11: 2022/11 | DG11: 2022/12 | DH11: 2023/01 | DI11: 2023/02 | DJ11: 2023/03 | DK11: 2023/04 | DL11: 2023/05 | DM11: 2023/06 | DN11: 2023/07 | DO11: 2023/08 | DP11: 2023/09 | DQ11: 2023/10 | DR11: 2023/11 | DS11: 2023/12 | DT11: 2024/01 | DU11: 2024/02 | DV11: 2024/03 | DW11: 2024/04 | DX11: 2024/05 | DY11: 2024/06 | DZ11: 2024/07 | EA11: 2024/08 | EB11: 2024/09 | EC11: 2024/10 | ED11: 2024/11 | EE11: 2024/12 | EF11: 2025/01 | EG11: 2025/02 | EH11: 2025/03 | EI11: 2025/04 | EJ11: 2025/05 | EK11: 2025/06 | EL11: 2025/07 | EM11: 平均值 | EN11: 標準差 | EO11: 夏普比率
A12: 10 | B12: =ROUND($D$10/A12,0) | C12: 0.098199502 | D12: 0.1028238 | E12: 0.038261781 | F12: 0.0073451094 | G12: 0.015156936 | H12: 0.043063012 | I12: 0.024997931 | J12: 0.018114183 | K12: 0.028025433 | L12: 0.034533577 | M12: 0.0036873954 | N12: 0.062468605 | O12: 0.019028095 | P12: 0.001749766 | Q12: 0.024578568 | R12: 0.016873412 | S12: 0.026055006 | T12: 0.0034974851 | U12: 0.020802966 | V12: -0.01054624 | W12: 0.058599399 | X12: 0.031253187 | Y12: 0.015597172 | Z12: 0.0034122483 | AA12: 0.015643859 | AB12: -0.0032343374 | AC12: 0.010718317 | AD12: 0.009132501 | AE12: 0.04658557 | AF12: 0.034669064 | AG12: 0.0091635467 | AH12: 0.024404385 | AI12: 0.012730192 | AJ12: 0.025824741 | AK12: -0.0062704289 | AL12: 0.036103997 | AM12: 0.013098318 | AN12: 0.047617448 | AO12: 0.020909476 | AP12: 0.010466975 | AQ12: -0.0016752757 | AR12: 0.030774647 | AS12: -0.0001147007 | AT12: 0.025082472 | AU12: 0.06350953 | AV12: 0.026560411 | AW12: 0.011774373 | AX12: 0.0081580672 | AY12: -0.0034325708 | AZ12: 0.056338485 | BA12: 0.070623312 | BB12: -0.0010424709 | BC12: -0.0022644607 | BD12: 0.050680413 | BE12: 0.046137741 | BF12: 0.009645787 | BG12: 0.0107746 | BH12: 0.023413018 | BI12: 0.030132927 | BJ12: 0.036180007 | BK12: 0.017434305 | BL12: 0.010525824 | BM12: 0.016801567 | BN12: 0.030037923 | BO12: 0.017330704 | BP12: 0.024810168 | BQ12: 0.018818526 | BR12: 0.025046499 | BS12: 0.027637535 | BT12: 0.02130586 | BU12: 0.035413041 | BV12: 0.025457017 | BW12: 0.052391898 | BX12: 0.018198986 | BY12: 0.051109523 | BZ12: 0.0070500167 | CA12: 0.008772382 | CB12: 0.056271327 | CC12: 0.054872423 | CD12: 0.041016507 | CE12: 0.14141655 | CF12: -0.0068181471 | CG12: 0.0028681923 | CH12: 0.014622227 | CI12: 0.026715049 | CJ12: 0.011022752 | CK12: 0.026440692 | CL12: 0.033333758 | CM12: 0.06443083 | CN12: 0.020062611 | CO12: 0.068320871 | CP12: 0.0053085747 | CQ12: 0.059017472 | CR12: 0.04794599 | CS12: 0.0057260433 | CT12: 0.031936085 | CU12: 0.023802843 | CV12: -0.0018180069 | CW12: 0.026773031 | CX12: 0.032881492 | CY12: 0.031468976 | CZ12: 0.087521582 | DA12: 0.030372588 | DB12: 0.076905202 | DC12: 0.025922932 | DD12: 0.015871145 | DE12: 0.033746356 | DF12: 0.048904276 | DG12: 0.043686976 | DH12: 0.032463432 | DI12: 0.053725325 | DJ12: 0.021108185 | DK12: 0.034140901 | DL12: 0.00054340704 | DM12: 0.021984778 | DN12: 0.028551139 | DO12: 0.030264991 | DP12: 0.058352004 | DQ12: 0.041185574 | DR12: 0.010317726 | DS12: 0.080446065 | DT12: 0.031115111 | DU12: 0.050063196 | DV12: -0.02047211 | DW12: 0.057897224 | DX12: 0.037626045 | DY12: 0.048638639 | DZ12: 0.0023579635 | EA12: 0.051998138 | EB12: 0.0035778632 | EC12: 0.013948493 | ED12: 0.0095002733 | EE12: 0.028166727 | EF12: 0.021832482 | EG12: 0.013834406 | EH12: 0.0087683038 | EI12: 0.0089612567 | EJ12: 0.036140391 | EK12: 0.050118013 | EL12: 0.016772717 | EM12: =AVERAGE(C12:EL12) | EN12: =STDEV(C12:EL12) | EO12: =EM12/EN12
A13: 20 | B13: =ROUND($D$10/A13,0) | C13: 0.12107776 | D13: 0.083505282 | E13: 0.049219109 | F13: 0.037987155 | G13: 0.015204703 | H13: 0.029251264 | I13: 0.02380771 | J13: 0.026404115 | K13: 0.017789949 | L13: 0.018673571 | M13: -0.019915206 | N13: 0.083003657 | O13: 0.02268123 | P13: -0.015955721 | Q13: 0.055097991 | R13: 0.027470093 | S13: 0.041135399 | T13: 0.013348455 | U13: 0.014617996 | V13: -0.0075051683 | W13: 0.079691017 | X13: 0.039812114 | Y13: 0.0092373913 | Z13: 0.01507365 | AA13: 0.020729237 | AB13: -0.016852038 | AC13: 0.0073530212 | AD13: -0.0030083609 | AE13: 0.044695273 | AF13: 0.032817536 | AG13: 0.0079574077 | AH13: 0.02626744 | AI13: 0.01195527 | AJ13: 0.0023719863 | AK13: -0.0099900198 | AL13: 0.034676361 | AM13: -0.0053863946 | AN13: 0.063432999 | AO13: 0.016168646 | AP13: 0.015675376 | AQ13: -0.004482465 | AR13: 0.033598562 | AS13: 0.01716864 | AT13: -0.0087646429 | AU13: 0.07301813 | AV13: 0.031979164 | AW13: 0.035176784 | AX13: -0.0026666727 | AY13: 0.0071781548 | AZ13: 0.065669863 | BA13: 0.073179702 | BB13: -0.008633787 | BC13: 0.0086069287 | BD13: 0.037273886 | BE13: 0.050521463 | BF13: 0.012356131 | BG13: -0.0025001803 | BH13: 0.025299915 | BI13: 0.044626637 | BJ13: 0.046151926 | BK13: 0.032887619 | BL13: 0.013965481 | BM13: 0.018988291 | BN13: 0.027466363 | BO13: 0.0094508943 | BP13: 0.020221679 | BQ13: 0.042239559 | BR13: 0.026424991 | BS13: 0.031524546 | BT13: 0.012182762 | BU13: 0.060633379 | BV13: 0.017125325 | BW13: 0.10489004 | BX13: 0.024517822 | BY13: 0.0488462 | BZ13: 0.0024459567 | CA13: 0.021057202 | CB13: 0.11090423 | CC13: 0.096289702 | CD13: 0.0488399 | CE13: 0.18420232 | CF13: -0.020554794 | CG13: 0.004295845 | CH13: 0.021255164 | CI13: 0.0021702088 | CJ13: 0.025000438 | CK13: 0.016635718 | CL13: 0.033705433 | CM13: 0.082791769 | CN13: 0.040250527 | CO13: 0.079115499 | CP13: 0.0059087102 | CQ13: 0.052498773 | CR13: 0.071519219 | CS13: 0.0032310065 | CT13: 0.028971683 | CU13: 0.035215498 | CV13: 0.00021046814 | CW13: 0.022720059 | CX13: -0.0049397916 | CY13: 0.048289922 | CZ13: 0.11297745 | DA13: 0.014829783 | DB13: 0.078082554 | DC13: 0.038784674 | DD13: 0.016442308 | DE13: 0.029035878 | DF13: 0.063934166 | DG13: 0.037529261 | DH13: 0.039090407 | DI13: 0.071009668 | DJ13: 0.0060368667 | DK13: 0.020804993 | DL13: 0.029014875 | DM13: 0.0080990213 | DN13: 0.032732131 | DO13: 0.03603869 | DP13: 0.062650721 | DQ13: 0.045352565 | DR13: 0.016606877 | DS13: 0.071305965 | DT13: 0.056443083 | DU13: 0.01231375 | DV13: -0.035576139 | DW13: 0.058892837 | DX13: 0.055875508 | DY13: 0.063495868 | DZ13: 0.0085362002 | EA13: 0.046460982 | EB13: 0.0019472343 | EC13: 0.016616407 | ED13: 0.00080413264 | EE13: 0.037157512 | EF13: 0.035981928 | EG13: 0.0056386689 | EH13: 0.010178486 | EI13: 0.01362226 | EJ13: 0.031971336 | EK13: 0.043586137 | EL13: 0.054200362 | EM13: =AVERAGE(C13:EL13) | EN13: =STDEV(C13:EL13) | EO13: =EM13/EN13
A14: 50 | B14: =ROUND($D$10/A14,0) | C14: 0.13220513 | D14: 0.1158128 | E14: 0.083639426 | F14: 0.047441584 | G14: 0.097449694 | H14: 0.076211003 | I14: 0.048575362 | J14: 0.060435533 | K14: 0.038115639 | L14: 0.036882667 | M14: 0.0083093355 | N14: 0.1459039 | O14: 0.025042768 | P14: -0.054679978 | Q14: 0.087609226 | R14: 0.057744307 | S14: 0.022934305 | T14: 0.006499499 | U14: -0.018672251 | V14: 0.00019718996 | W14: 0.10108001 | X14: 0.045064903 | Y14: -0.04063813 | Z14: 0.040558913 | AA14: -0.014646954 | AB14: -0.063311692 | AC14: -0.015948313 | AD14: 0.006953009 | AE14: -0.0012768812 | AF14: 0.072375898 | AG14: 0.01869998 | AH14: 0.056536549 | AI14: -0.0042440842 | AJ14: 0.034305962 | AK14: 0.0027126283 | AL14: 0.042015348 | AM14: 0.0036458821 | AN14: 0.10005894 | AO14: -0.016455989 | AP14: 0.024294074 | AQ14: 0.012665591 | AR14: 0.062379456 | AS14: 0.054707453 | AT14: 0.014220908 | AU14: 0.10970669 | AV14: 0.033710826 | AW14: 0.037803967 | AX14: 0.033694523 | AY14: 0.045898948 | AZ14: 0.0053410775 | BA14: 0.091311505 | BB14: -0.077736356 | BC14: -0.019339632 | BD14: 0.027350925 | BE14: 0.033401944 | BF14: -0.0056265666 | BG14: 0.013689418 | BH14: 0.079144771 | BI14: 0.054726627 | BJ14: 0.024895583 | BK14: -0.021044327 | BL14: 0.0077225927 | BM14: 0.0070477969 | BN14: 0.011205903 | BO14: 0.017282477 | BP14: -0.048228295 | BQ14: 0.036274606 | BR14: -0.00040855165 | BS14: 0.051997883 | BT14: -0.016902937 | BU14: 0.10739504 | BV14: 0.013662741 | BW14: 0.14517951 | BX14: -0.0039873386 | BY14: 0.098203766 | BZ14: 0.049772174 | CA14: 0.016383762 | CB14: 0.11179425 | CC14: 0.087443826 | CD14: 0.056136825 | CE14: 0.20666802 | CF14: 0.034503602 | CG14: -0.087124277 | CH14: 0.025271458 | CI14: 0.034520727 | CJ14: 0.057339496 | CK14: 0.031409433 | CL14: 0.064512373 | CM14: 0.09007073 | CN14: 0.063403707 | CO14: 0.17790312 | CP14: 0.074964725 | CQ14: 0.059958595 | CR14: 0.04962061 | CS14: 0.023427351 | CT14: 0.074203932 | CU14: 0.086087366 | CV14: 0.017672945 | CW14: 0.0094659147 | CX14: -0.029742266 | CY14: 0.052538179 | CZ14: 0.1016529 | DA14: 0.047399854 | DB14: 0.083638879 | DC14: 0.053791589 | DD14: -0.035820503 | DE14: 0.012156801 | DF14: 0.16325273 | DG14: 0.043741274 | DH14: 0.062926026 | DI14: 0.1289201 | DJ14: 0.013777168 | DK14: 0.035525439 | DL14: 0.01105822 | DM14: 0.019116465 | DN14: 0.054850333 | DO14: 0.079032555 | DP14: 0.060649114 | DQ14: 0.017913622 | DR14: 0.022141557 | DS14: 0.053892649 | DT14: 0.10430461 | DU14: 0.05484965 | DV14: -0.0046847071 | DW14: 0.07629508 | DX14: 0.096137869 | DY14: 0.060570738 | DZ14: 0.0078440144 | EA14: 0.062943118 | EB14: -0.030713337 | EC14: -0.0037857106 | ED14: 0.039337541 | EE14: 0.012534993 | EF14: 0.059075573 | EG14: -0.00034522038 | EH14: 0.052029659 | EI14: 0.0056953674 | EJ14: 0.026532326 | EK14: 0.035700626 | EL14: 0.047771192 | EM14: =AVERAGE(C14:EL14) | EN14: =STDEV(C14:EL14) | EO14: =EM14/EN14
A15: 110 | B15: =ROUND($D$10/A15,0) | C15: 0.24155842 | D15: 0.17378891 | E15: 0.074569663 | F15: 0.081782027 | G15: 0.13793788 | H15: 0.08181565 | I15: 0.099572773 | J15: 0.061574402 | K15: 0.031508098 | L15: -0.022753363 | M15: 0.14710226 | N15: 0.24738805 | O15: 0.04656045 | P15: -0.067357961 | Q15: 0.042372617 | R15: 0.0014163966 | S15: 0.078073059 | T15: 0.031600514 | U15: -0.084116384 | V15: -0.024048884 | W15: 0.062669826 | X15: 0.059017947 | Y15: -0.0064150713 | Z15: 0.079971018 | AA15: -0.02379685 | AB15: -0.1096631 | AC15: -0.028054512 | AD15: 0.013590293 | AE15: -0.084685819 | AF15: 0.040748555 | AG15: -0.014840092 | AH15: -0.0066286236 | AI15: 0.019561053 | AJ15: -0.012097322 | AK15: 0.011510087 | AL15: 0.028443609 | AM15: 0.004873346 | AN15: 0.18216642 | AO15: 0.047046882 | AP15: 0.010039374 | AQ15: -0.016850399 | AR15: 0.04832012 | AS15: 0.04517461 | AT15: -0.0055691296 | AU15: 0.13494562 | AV15: 0.046574913 | AW15: 0.090158082 | AX15: 0.065152924 | AY15: 0.0076968983 | AZ15: 0.032014302 | BA15: 0.16145099 | BB15: -0.091035931 | BC15: 0.034144742 | BD15: -0.020834013 | BE15: 0.054722501 | BF15: 0.057792734 | BG15: 0.013021552 | BH15: 0.068660013 | BI15: 0.061863404 | BJ15: 0.10657677 | BK15: -0.022584607 | BL15: -0.0080895923 | BM15: 0.035518523 | BN15: -0.03567062 | BO15: 0.058437943 | BP15: -0.098443455 | BQ15: 0.039766138 | BR15: 0.0527355 | BS15: 0.067963755 | BT15: 0.012059676 | BU15: 0.053351351 | BV15: 0.033638789 | BW15: 0.1942695 | BX15: 0.043155484 | BY15: 0.1170215 | BZ15: 0.08677276 | CA15: 0.031422676 | CB15: 0.064451767 | CC15: 0.12139252 | CD15: 0.095156377 | CE15: 0.12056337 | CF15: 0.033561833 | CG15: -0.259149 | CH15: -0.022955774 | CI15: 0.022912017 | CJ15: -0.0066819984 | CK15: 0.068437953 | CL15: 0.095137818 | CM15: 0.053281165 | CN15: 0.012280562 | CO15: 0.1646968 | CP15: 0.0078391201 | CQ15: 0.062374471 | CR15: 0.034388284 | CS15: 0.024648671 | CT15: 0.019878054 | CU15: 0.17082912 | CV15: 0.029146428 | CW15: -0.01127938 | CX15: -0.040029384 | CY15: 0.024694072 | CZ15: 0.14391984 | DA15: 0.068598068 | DB15: 0.039932393 | DC15: 0.068810504 | DD15: -0.1869214 | DE15: 0.057837856 | DF15: 0.29943563 | DG15: 0.040171633 | DH15: 0.13218755 | DI15: 0.020190924 | DJ15: 0.028863595 | DK15: 0.083677801 | DL15: -0.001603336 | DM15: 0.012983297 | DN15: -0.014486234 | DO15: 0.13844702 | DP15: -0.013411426 | DQ15: 0.043565134 | DR15: 0.016783388 | DS15: 0.052192903 | DT15: 0.026593189 | DU15: 0.083734456 | DV15: -0.018984707 | DW15: 0.0082263342 | DX15: 0.038004406 | DY15: 0.11749143 | DZ15: 0.0045174473 | EA15: 0.064740279 | EB15: -0.07659086 | EC15: 0.0049872126 | ED15: 0.052111778 | EE15: 0.0096175593 | EF15: 0.044912949 | EG15: -0.0060486026 | EH15: 0.056251058 | EI15: 0.028455499 | EJ15: 0.057632244 | EK15: 0.03490671 | EL15: -0.041557681 | EM15: =AVERAGE(C15:EL15) | EN15: =STDEV(C15:EL15) | EO15: =EM15/EN15
A16: 120 | B16: =ROUND($D$10/A16,0) | C16: 0.26072771 | D16: 0.18425851 | E16: 0.074485661 | F16: 0.053057197 | G16: 0.15493728 | H16: 0.082581289 | I16: 0.081776721 | J16: 0.047297176 | K16: 0.029838912 | L16: -0.024637175 | M16: 0.15885956 | N16: 0.28291581 | O16: 0.055861449 | P16: -0.079649562 | Q16: 0.048020331 | R16: -0.0085771421 | S16: 0.068127752 | T16: 0.028224062 | U16: -0.071987231 | V16: -0.016175265 | W16: 0.048227746 | X16: 0.067104752 | Y16: -0.016956103 | Z16: 0.080735182 | AA16: -0.039190475 | AB16: -0.1209893 | AC16: -0.029167401 | AD16: 0.018883824 | AE16: -0.089884957 | AF16: 0.047054932 | AG16: 0.010493666 | AH16: 0.012400629 | AI16: 0.029381148 | AJ16: -0.035720083 | AK16: -0.020334193 | AL16: 0.024777898 | AM16: -0.0018251438 | AN16: 0.11265762 | AO16: 0.044419672 | AP16: 0.022438398 | AQ16: -0.010727433 | AR16: 0.10277024 | AS16: 0.043618132 | AT16: -0.0049592347 | AU16: 0.13870065 | AV16: 0.065058029 | AW16: 0.09483437 | AX16: 0.063420661 | AY16: -0.0047113984 | AZ16: 0.026619999 | BA16: 0.15831023 | BB16: -0.11648751 | BC16: 0.034807397 | BD16: -0.025047737 | BE16: 0.04726161 | BF16: 0.059047857 | BG16: 0.021354945 | BH16: 0.059214979 | BI16: 0.071250388 | BJ16: 0.11634242 | BK16: -0.036488351 | BL16: -0.010898518 | BM16: 0.033996139 | BN16: -0.021653837 | BO16: 0.041235222 | BP16: -0.044135395 | BQ16: 0.046695972 | BR16: 0.06207829 | BS16: 0.078711297 | BT16: 0.012797701 | BU16: 0.04248524 | BV16: 0.026126171 | BW16: 0.21283064 | BX16: 0.046677909 | BY16: 0.13162601 | BZ16: 0.079934572 | CA16: 0.02905291 | CB16: 0.065264696 | CC16: 0.069042888 | CD16: 0.10645434 | CE16: 0.069763241 | CF16: 0.044339369 | CG16: -0.24404791 | CH16: -0.010630558 | CI16: 0.020906241 | CJ16: 0.012173058 | CK16: 0.10868493 | CL16: 0.11325697 | CM16: 0.052124071 | CN16: 0.015068491 | CO16: 0.18300397 | CP16: 0.013523032 | CQ16: 0.064439236 | CR16: 0.030724192 | CS16: 0.015413045 | CT16: 0.028909286 | CU16: 0.17289622 | CV16: 0.020301295 | CW16: -0.0065589084 | CX16: -0.026923303 | CY16: 0.029494109 | CZ16: 0.15985824 | DA16: 0.095888549 | DB16: 0.057360445 | DC16: 0.076411121 | DD16: -0.20966156 | DE16: 0.047239952 | DF16: 0.32192975 | DG16: 0.044449393 | DH16: 0.15270632 | DI16: 0.043303131 | DJ16: 0.038300463 | DK16: 0.083260594 | DL16: -0.0086769132 | DM16: -0.036759747 | DN16: 0.0016661285 | DO16: 0.17548977 | DP16: 0.0051931575 | DQ16: 0.038922426 | DR16: 0.031953669 | DS16: 0.052113583 | DT16: 0.016405906 | DU16: 0.085341215 | DV16: -0.01917334 | DW16: 0.037742997 | DX16: 0.044218675 | DY16: 0.1144703 | DZ16: 0.013111669 | EA16: 0.084234522 | EB16: -0.073319027 | EC16: 0.014751246 | ED16: 0.059180061 | EE16: 0.011537607 | EF16: 0.06024264 | EG16: -0.0016212791 | EH16: 0.068018973 | EI16: 0.02581173 | EJ16: 0.055428966 | EK16: 0.03627353 | EL16: -0.02035781 | EM16: =AVERAGE(C16:EL16) | EN16: =STDEV(C16:EL16) | EO16: =EM16/EN16
A17: 130 | B17: =ROUND($D$10/A17,0) | C17: 0.23789705 | D17: 0.18133129 | E17: 0.076702626 | F17: 0.056491027 | G17: 0.16879685 | H17: 0.039953295 | I17: 0.081303626 | J17: 0.052886326 | K17: 0.016624608 | L17: -0.0074515064 | M17: 0.1805564 | N17: 0.31927896 | O17: 0.026574381 | P17: -0.087196549 | Q17: 0.050219077 | R17: 0.00020809019 | S17: 0.068954659 | T17: 0.032232624 | U17: -0.073605682 | V17: -0.026973216 | W17: 0.045379488 | X17: 0.060280514 | Y17: -0.0274415 | Z17: 0.085830026 | AA17: -0.045854851 | AB17: -0.12080229 | AC17: -0.039488261 | AD17: -0.029598498 | AE17: -0.096717574 | AF17: 0.032582227 | AG17: 0.022511194 | AH17: 0.0020603423 | AI17: 0.028114738 | AJ17: -0.042559656 | AK17: -0.018535818 | AL17: 0.034172977 | AM17: 0.0011645325 | AN17: 0.12461249 | AO17: 0.028750924 | AP17: 0.032607245 | AQ17: -0.033026661 | AR17: 0.054951162 | AS17: 0.051001532 | AT17: -0.028459489 | AU17: 0.13777321 | AV17: 0.072187215 | AW17: 0.11400026 | AX17: 0.075132748 | AY17: -0.004833033 | AZ17: 0.026112753 | BA17: 0.1683477 | BB17: -0.14193613 | BC17: 0.052331596 | BD17: -0.01583429 | BE17: 0.036598393 | BF17: 0.02335791 | BG17: -0.010876605 | BH17: 0.064097656 | BI17: 0.057207807 | BJ17: 0.12527426 | BK17: -0.040770554 | BL17: 0.005582673 | BM17: 0.040864884 | BN17: -0.017785292 | BO17: 0.025806242 | BP17: -0.051687061 | BQ17: 0.054619954 | BR17: 0.091050124 | BS17: 0.089823174 | BT17: 0.0012266991 | BU17: 0.071890941 | BV17: 0.02377692 | BW17: 0.23425066 | BX17: 0.051844993 | BY17: 0.09546082 | BZ17: 0.087603173 | CA17: 0.029020117 | CB17: 0.066333613 | CC17: 0.064406574 | CD17: 0.11765382 | CE17: 0.088883514 | CF17: 0.061114146 | CG17: -0.15746127 | CH17: 0.0083677189 | CI17: 0.0067953763 | CJ17: 0.020741155 | CK17: 0.11844014 | CL17: 0.10824632 | CM17: 0.038686091 | CN17: 0.037685796 | CO17: 0.13711923 | CP17: -0.0011679112 | CQ17: 0.074588266 | CR17: 0.029283681 | CS17: 0.014748014 | CT17: 0.039818933 | CU17: 0.14233857 | CV17: 0.012012141 | CW17: -0.0092302209 | CX17: -0.014032075 | CY17: 0.024199713 | CZ17: 0.16357001 | DA17: 0.084473678 | DB17: 0.058532683 | DC17: 0.068142592 | DD17: 0.048534467 | DE17: 0.06393877 | DF17: 0.34811953 | DG17: 0.050927878 | DH17: 0.17700917 | DI17: 0.05902996 | DJ17: 0.040386118 | DK17: 0.095776785 | DL17: -0.014990768 | DM17: -0.043442597 | DN17: 0.0066885263 | DO17: 0.1863991 | DP17: 0.0085510285 | DQ17: 0.039336151 | DR17: -0.015658501 | DS17: 0.040247977 | DT17: 0.0056014247 | DU17: 0.094942711 | DV17: -0.029012843 | DW17: 0.025002201 | DX17: 0.056955272 | DY17: 0.14093028 | DZ17: 0.0031834454 | EA17: 0.10515141 | EB17: -0.076530001 | EC17: -0.012176775 | ED17: 0.051599441 | EE17: 0.02611294 | EF17: 0.07172012 | EG17: 0.028156438 | EH17: 0.059073225 | EI17: 0.022829268 | EJ17: 0.044788384 | EK17: 0.044324995 | EL17: -0.019339647 | EM17: =AVERAGE(C17:EL17) | EN17: =STDEV(C17:EL17) | EO17: =EM17/EN17
A18: 150 | B18: =ROUND($D$10/A18,0) | C18: 0.24368729 | D18: 0.19928275 | E18: 0.10018499 | F18: 0.029665957 | G18: 0.19210419 | H18: 0.062052684 | I18: 0.052263615 | J18: 0.057694178 | K18: 0.045576886 | L18: -0.0473979 | M18: 0.18725155 | N18: 0.36380387 | O18: 0.029239173 | P18: -0.10700477 | Q18: 0.056066275 | R18: 0.02213484 | S18: 0.045877349 | T18: 0.034061671 | U18: -0.06371502 | V18: -0.017392338 | W18: 0.050611891 | X18: 0.049325477 | Y18: -0.055793282 | Z18: 0.086003954 | AA18: -0.039881885 | AB18: -0.13770845 | AC18: -0.012020657 | AD18: -0.026866366 | AE18: -0.12960198 | AF18: 0.026070316 | AG18: -0.0013390269 | AH18: 0.0076207714 | AI18: 0.06300246 | AJ18: -0.030587097 | AK18: -0.063703106 | AL18: 0.051371435 | AM18: 0.0045321879 | AN18: 0.091788218 | AO18: 0.036526969 | AP18: 0.050736193 | AQ18: 0.0087928858 | AR18: 0.060067609 | AS18: 0.055600683 | AT18: -0.028113715 | AU18: 0.13825374 | AV18: 0.07876463 | AW18: 0.11599835 | AX18: 0.10736476 | AY18: -0.0052270055 | AZ18: 0.04134964 | BA18: 0.17834058 | BB18: -0.1685758 | BC18: 0.052806456 | BD18: -0.010232032 | BE18: 0.044777879 | BF18: 0.043881157 | BG18: 0.00029371261 | BH18: 0.055177647 | BI18: 0.050528764 | BJ18: 0.0227653 | BK18: -0.040177172 | BL18: -0.0020994624 | BM18: 0.032915683 | BN18: -0.020448989 | BO18: 0.058572777 | BP18: -0.058439021 | BQ18: 0.060751941 | BR18: 0.090339621 | BS18: 0.11561647 | BT18: -0.0035308846 | BU18: 0.089383805 | BV18: 0.027819769 | BW18: 0.23979131 | BX18: 0.035209839 | BY18: 0.087918547 | BZ18: 0.10981457 | CA18: 0.035369974 | CB18: 0.07872429 | CC18: 0.069815721 | CD18: 0.12298069 | CE18: 0.069460899 | CF18: 0.062990956 | CG18: -0.17099534 | CH18: 0.027540592 | CI18: -0.0043287818 | CJ18: 0.032796109 | CK18: 0.082295295 | CL18: 0.11221187 | CM18: 0.023792103 | CN18: 0.035538223 | CO18: 0.16749636 | CP18: -0.015318236 | CQ18: 0.089820081 | CR18: 0.038174056 | CS18: 0.038558232 | CT18: 0.030788312 | CU18: 0.14258985 | CV18: 0.013232663 | CW18: -0.033294541 | CX18: -0.016508224 | CY18: 0.011890198 | CZ18: 0.17469678 | DA18: 0.076047417 | DB18: 0.05554653 | DC18: 0.065499462 | DD18: 0.071532874 | DE18: 0.053332797 | DF18: 0.36199941 | DG18: 0.061064663 | DH18: 0.20586588 | DI18: 0.057437414 | DJ18: 0.047666267 | DK18: 0.067768733 | DL18: -0.018669971 | DM18: -0.038027462 | DN18: 0.015097597 | DO18: 0.21535048 | DP18: 0.026587698 | DQ18: 0.02645985 | DR18: 4.8667407e-05 | DS18: 0.014585284 | DT18: -0.0015115426 | DU18: 0.11917142 | DV18: -0.046161208 | DW18: 0.05781256 | DX18: 0.078512284 | DY18: 0.17083084 | DZ18: 0.010184364 | EA18: 0.13955198 | EB18: -0.10018444 | EC18: -0.014626816 | ED18: 0.044547846 | EE18: 0.020407386 | EF18: 0.082038992 | EG18: 0.041553197 | EH18: 0.046358823 | EI18: 0.014951567 | EJ18: 0.062676685 | EK18: 0.045567285 | EL18: 0.0085219986 | EM18: =AVERAGE(C18:EL18) | EN18: =STDEV(C18:EL18) | EO18: =EM18/EN18
A19: 180 | B19: =ROUND($D$10/A19,0) | C19: 0.25825037 | D19: 0.20816772 | E19: 0.073818854 | F19: 0.018539269 | G19: 0.2217515 | H19: 0.08653379 | I19: 0.057039606 | J19: 0.11748327 | K19: 0.04288124 | L19: -0.053179775 | M19: 0.23290702 | N19: 0.41276888 | O19: 0.025799248 | P19: -0.091939631 | Q19: 0.067562476 | R19: 0.020264746 | S19: 0.030650409 | T19: 0.0022033975 | U19: -0.064758127 | V19: 0.034560721 | W19: 0.015187091 | X19: 0.044013435 | Y19: -0.080435135 | Z19: 0.04452044 | AA19: -0.052724182 | AB19: -0.098178582 | AC19: -0.010925294 | AD19: -0.041380571 | AE19: -0.14928898 | AF19: -0.039012882 | AG19: -0.018428906 | AH19: -0.029547768 | AI19: 0.084173954 | AJ19: -0.01496907 | AK19: -0.091540826 | AL19: 0.059399001 | AM19: 0.028146403 | AN19: 0.090228952 | AO19: 0.037871326 | AP19: 0.055140916 | AQ19: 0.043237106 | AR19: 0.061340989 | AS19: 0.076775685 | AT19: -0.059961129 | AU19: 0.15211368 | AV19: 0.090115408 | AW19: 0.1288215 | AX19: 0.12440528 | AY19: -0.013812107 | AZ19: 0.054875564 | BA19: 0.18450106 | BB19: -0.18591535 | BC19: 0.049716397 | BD19: -0.020372363 | BE19: 0.056983503 | BF19: 0.056130858 | BG19: 0.0039988279 | BH19: 0.042278233 | BI19: 0.05244379 | BJ19: 0.024018118 | BK19: -0.089766859 | BL19: -0.0022156981 | BM19: 0.032077389 | BN19: -0.013391265 | BO19: 0.00052556407 | BP19: -0.068391037 | BQ19: 0.069296558 | BR19: 0.05689735 | BS19: 0.10451285 | BT19: -0.035563239 | BU19: 0.09834372 | BV19: 0.049504513 | BW19: 0.27753079 | BX19: 0.012701726 | BY19: 0.094645219 | BZ19: 0.14474202 | CA19: 0.038040906 | CB19: 0.013789671 | CC19: 0.049243604 | CD19: 0.088535197 | CE19: 0.037209123 | CF19: 0.066352884 | CG19: -0.21243622 | CH19: 0.045911153 | CI19: 0.019186101 | CJ19: 0.050437678 | CK19: 0.067004504 | CL19: 0.14149225 | CM19: 0.024237295 | CN19: 0.031665875 | CO19: 0.18612998 | CP19: -0.0041130119 | CQ19: 0.11647177 | CR19: 0.036247753 | CS19: 0.040969269 | CT19: 0.036441796 | CU19: 0.044209008 | CV19: 0.019138754 | CW19: -0.025058129 | CX19: -0.013126101 | CY19: 0.0039358045 | CZ19: 0.1272547 | DA19: 0.044898319 | DB19: 0.058652618 | DC19: 0.049282151 | DD19: 0.064085968 | DE19: 0.022369053 | DF19: 0.20002704 | DG19: 0.066791453 | DH19: 0.24633455 | DI19: 0.076023014 | DJ19: 0.050612658 | DK19: 0.062506167 | DL19: 0.013735771 | DM19: -0.065564814 | DN19: -0.015315069 | DO19: 0.21989532 | DP19: 0.03180837 | DQ19: 0.01466046 | DR19: -0.005294897 | DS19: 0.00044112623 | DT19: 0.0029882826 | DU19: 0.11597873 | DV19: -0.053911897 | DW19: 0.075899946 | DX19: 0.093094439 | DY19: 0.20371081 | DZ19: 0.0066249987 | EA19: 0.16979568 | EB19: -0.10991123 | EC19: -0.069379781 | ED19: 0.052699375 | EE19: 0.030408355 | EF19: 0.072902632 | EG19: 0.090100997 | EH19: 0.036970449 | EI19: -0.020693682 | EJ19: 0.048870155 | EK19: 0.041623588 | EL19: -0.023768186 | EM19: =AVERAGE(C19:EL19) | EN19: =STDEV(C19:EL19) | EO19: =EM19/EN19
A20: 200 | B20: =ROUND($D$10/A20,0) | C20: 0.24103575 | D20: 0.22395276 | E20: 0.048815066 | F20: -0.027411849 | G20: 0.24069195 | H20: 0.12733286 | I20: 0.027935542 | J20: 0.13320729 | K20: 0.080698574 | L20: -0.057745399 | M20: 0.27765417 | N20: 0.4793614 | O20: -0.026923376 | P20: -0.049665695 | Q20: 0.086440522 | R20: 0.045930791 | S20: 0.034884115 | T20: -0.012441505 | U20: -0.044860999 | V20: 0.050664571 | W20: -0.0051830151 | X20: 0.064058501 | Y20: -0.046750321 | Z20: 0.027386029 | AA20: -0.071851059 | AB20: -0.089106463 | AC20: -0.010208304 | AD20: 0.0074482705 | AE20: -0.1810854 | AF20: -0.05980416 | AG20: -0.026132473 | AH20: -0.044377376 | AI20: 0.10857716 | AJ20: -0.015321798 | AK20: -0.11794481 | AL20: 0.06732844 | AM20: 0.028483107 | AN20: 0.09467796 | AO20: 0.030197797 | AP20: 0.076747301 | AQ20: 0.053722126 | AR20: 0.062905685 | AS20: 0.076790285 | AT20: -0.053733446 | AU20: 0.17397435 | AV20: 0.09772368 | AW20: 0.1543811 | AX20: 0.15829798 | AY20: -0.0073666499 | AZ20: 0.050576081 | BA20: 0.21454655 | BB20: -0.23487318 | BC20: 0.058932367 | BD20: -0.015998214 | BE20: 0.074243787 | BF20: 0.063250109 | BG20: -0.048084464 | BH20: 0.055872392 | BI20: 0.084860688 | BJ20: 0.019418236 | BK20: -0.044707859 | BL20: -0.011810365 | BM20: 0.039763244 | BN20: -0.036520911 | BO20: 0.0021370487 | BP20: -0.00070586227 | BQ20: -0.026978507 | BR20: 0.049783819 | BS20: 0.1138439 | BT20: -0.057929858 | BU20: 0.10665679 | BV20: 0.052158667 | BW20: 0.3280518 | BX20: -0.016073797 | BY20: 0.09275567 | BZ20: 0.18472509 | CA20: 0.053134159 | CB20: 0.022364425 | CC20: 0.034305446 | CD20: 0.099996406 | CE20: 0.032857624 | CF20: 0.094988356 | CG20: -0.249594 | CH20: 0.044034228 | CI20: 0.053347128 | CJ20: 0.0151593 | CK20: 0.059948437 | CL20: 0.14406367 | CM20: 0.0083382579 | CN20: 0.016769923 | CO20: 0.21784067 | CP20: -0.028663181 | CQ20: 0.15086802 | CR20: 0.045103738 | CS20: 0.058574013 | CT20: 0.057906913 | CU20: 0.0012896643 | CV20: 0.028072663 | CW20: -0.017255597 | CX20: 0.0058017888 | CY20: 0.026579554 | CZ20: 0.14371247 | DA20: 0.022041977 | DB20: 0.07696807 | DC20: 0.051707993 | DD20: 0.068809216 | DE20: -0.0047055402 | DF20: 0.22982781 | DG20: 0.074371572 | DH20: 0.30439257 | DI20: 0.12416072 | DJ20: 0.11771965 | DK20: 0.07330978 | DL20: 0.010650687 | DM20: -0.0075266043 | DN20: -0.0036156517 | DO20: 0.25866686 | DP20: 0.018071021 | DQ20: 0.010109114 | DR20: -0.04085811 | DS20: -0.028698637 | DT20: -0.022199103 | DU20: 0.1160416 | DV20: -0.0093474836 | DW20: 0.074901762 | DX20: 0.13335426 | DY20: 0.15785681 | DZ20: -0.0011329373 | EA20: 0.19947335 | EB20: -0.11071072 | EC20: -0.048932642 | ED20: 0.037586415 | EE20: 0.034307819 | EF20: 0.084458715 | EG20: 0.11162587 | EH20: 0.056573319 | EI20: -0.016322785 | EJ20: 0.062018698 | EK20: 0.049176622 | EL20: -0.044597853 | EM20: =AVERAGE(C20:EL20) | EN20: =STDEV(C20:EL20) | EO20: =EM20/EN20
A21: 256 | B21: =ROUND($D$10/A21,0) | C21: 0.24900647 | D21: 0.18724832 | E21: 0.070282274 | F21: 0.069409277 | G21: 0.21346539 | H21: 0.083509199 | I21: 0.014111278 | J21: 0.13674292 | K21: 0.064334981 | L21: -0.04172274 | M21: 0.29690459 | N21: 0.58489126 | O21: -0.13927749 | P21: -0.071494214 | Q21: 0.12104639 | R21: 0.081597114 | S21: 0.055538615 | T21: -0.049861751 | U21: -0.015792012 | V21: 0.060250492 | W21: -0.031960015 | X21: 0.072208782 | Y21: -0.017106239 | Z21: 0.023066614 | AA21: -0.0241396 | AB21: -0.10665511 | AC21: -0.064884758 | AD21: 0.01697952 | AE21: -0.075054766 | AF21: -0.071446304 | AG21: 0.0049639771 | AH21: -0.015982702 | AI21: 0.14542094 | AJ21: -0.007782032 | AK21: -0.16871167 | AL21: 0.11096215 | AM21: -0.0078331086 | AN21: 0.11999762 | AO21: 0.075524155 | AP21: 0.092235425 | AQ21: 0.077644737 | AR21: 0.087781597 | AS21: 0.13446366 | AT21: -0.045504691 | AU21: 0.1963969 | AV21: 0.089659121 | AW21: 0.18303436 | AX21: 0.15652081 | AY21: -0.015847564 | AZ21: 0.061468477 | BA21: 0.16630847 | BB21: -0.27638756 | BC21: 0.066355806 | BD21: 0.0077711636 | BE21: 0.085309526 | BF21: 0.07233146 | BG21: -0.047185488 | BH21: 0.040162712 | BI21: 0.046273769 | BJ21: 0.021522475 | BK21: -0.072723115 | BL21: -0.0038953473 | BM21: 0.076479522 | BN21: -0.039097178 | BO21: 0.025640602 | BP21: 0.0072557031 | BQ21: -0.063888364 | BR21: 0.013625509 | BS21: 0.15347556 | BT21: -0.090003492 | BU21: 0.12746595 | BV21: -0.0040664933 | BW21: 0.37017575 | BX21: -0.033159726 | BY21: 0.076881614 | BZ21: 0.25140178 | CA21: 0.0987061 | CB21: 0.036725783 | CC21: -0.0080189543 | CD21: 0.11353463 | CE21: 0.031129962 | CF21: 0.11831344 | CG21: -0.34112741 | CH21: 0.08945484 | CI21: 0.085122704 | CJ21: -0.049523063 | CK21: 0.08237095 | CL21: 0.085330885 | CM21: -0.038292791 | CN21: 0.025976275 | CO21: 0.2413941 | CP21: -0.050765086 | CQ21: 0.13610543 | CR21: 0.041319889 | CS21: 0.030346331 | CT21: 0.067406807 | CU21: 0.0080967812 | CV21: 0.058257806 | CW21: -0.038070043 | CX21: 0.017597304 | CY21: 0.0083566596 | CZ21: 0.11248761 | DA21: 0.018335652 | DB21: 0.071461214 | DC21: 0.063142265 | DD21: 0.077512678 | DE21: 0.05827113 | DF21: 0.28613086 | DG21: 0.050042124 | DH21: 0.35821167 | DI21: 0.15186657 | DJ21: 0.11885608 | DK21: 0.076846385 | DL21: 0.038155771 | DM21: -0.024201303 | DN21: 0.0089304946 | DO21: 0.33245868 | DP21: 0.012569221 | DQ21: 0.013463589 | DR21: -0.05355699 | DS21: -0.011682443 | DT21: -0.028890923 | DU21: 0.087036162 | DV21: -0.037688688 | DW21: 0.10898332 | DX21: 0.099724611 | DY21: 0.23479842 | DZ21: 0.006480967 | EA21: 0.14828604 | EB21: -0.10879362 | EC21: -0.059634219 | ED21: 0.045023016 | EE21: 0.031907537 | EF21: 0.08441724 | EG21: 0.095683429 | EH21: 0.037275271 | EI21: -0.0022718701 | EJ21: 0.051359973 | EK21: 0.0684961 | EL21: -0.044194553 | EM21: =AVERAGE(C21:EL21) | EN21: =STDEV(C21:EL21) | EO21: =EM21/EN21
A22: 400 | B22: =ROUND($D$10/A22,0) | C22: 0.28886619 | D22: 0.036573722 | E22: -0.017355099 | F22: 0.13986745 | G22: 0.23294542 | H22: 0.068510694 | I22: 0.017437343 | J22: 0.1042535 | K22: 0.02865678 | L22: 0.0039536714 | M22: 0.18466279 | N22: 0.75614344 | O22: -0.066442332 | P22: -0.090630874 | Q22: 0.11674113 | R22: 0.088674366 | S22: 0.10335105 | T22: 0.11348699 | U22: -0.044683532 | V22: 0.067362611 | W22: -0.032845179 | X22: 0.020811276 | Y22: -0.0062742308 | Z22: 0.036895251 | AA22: -0.064222746 | AB22: -0.1086951 | AC22: -0.059633 | AD22: 0.0089391604 | AE22: -0.09345467 | AF22: -0.10574116 | AG22: -0.026744271 | AH22: -0.027713882 | AI22: 0.14115608 | AJ22: -0.035833702 | AK22: -0.2128192 | AL22: 0.036840806 | AM22: 0.02097556 | AN22: 0.15748109 | AO22: 0.098839477 | AP22: 0.11224456 | AQ22: 0.12405807 | AR22: 0.082546725 | AS22: 0.16458944 | AT22: 0.028324858 | AU22: 0.27983615 | AV22: 0.12776278 | AW22: 0.22949323 | AX22: 0.012925712 | AY22: -0.015907347 | AZ22: 0.063956461 | BA22: 0.17858893 | BB22: -0.36382184 | BC22: 0.069078606 | BD22: 0.038662233 | BE22: 0.12811129 | BF22: 0.068274694 | BG22: -0.045741297 | BH22: 0.0096564663 | BI22: 0.082345467 | BJ22: -0.0185016 | BK22: -0.048315241 | BL22: -0.071294539 | BM22: 0.096285192 | BN22: -0.045815705 | BO22: 0.035409751 | BP22: 0.0023376902 | BQ22: -0.093758413 | BR22: 0.03293667 | BS22: 0.095996132 | BT22: -0.10520092 | BU22: 0.15266741 | BV22: -0.00051095637 | BW22: 0.51753358 | BX22: -0.031911449 | BY22: 0.050267437 | BZ22: 0.27962934 | CA22: 0.11040703 | CB22: 0.043804174 | CC22: -0.125104 | CD22: 0.098739628 | CE22: 0.013503449 | CF22: 0.10274598 | CG22: -0.30280912 | CH22: -0.026761118 | CI22: 0.063879461 | CJ22: -0.043655547 | CK22: 0.00057710985 | CL22: 0.11491158 | CM22: -0.047372368 | CN22: -0.0020954333 | CO22: 0.1715297 | CP22: 0.062505224 | CQ22: 0.0037237388 | CR22: 0.0447396 | CS22: 0.031092056 | CT22: 0.095120869 | CU22: -0.0057338505 | CV22: 0.078063152 | CW22: -0.029961109 | CX22: 0.045295209 | CY22: 0.0059281439 | CZ22: 0.18697885 | DA22: 0.022473098 | DB22: 0.054041622 | DC22: 0.084168565 | DD22: 0.056721152 | DE22: 0.09881659 | DF22: 0.38966763 | DG22: 0.074791032 | DH22: 0.12640435 | DI22: 0.22468947 | DJ22: 0.10351464 | DK22: 0.072696131 | DL22: 0.049532288 | DM22: -0.023144336 | DN22: -0.031697144 | DO22: 0.076824978 | DP22: -0.038861921 | DQ22: 0.051850202 | DR22: -0.0712363 | DS22: -0.039948517 | DT22: -0.043681446 | DU22: 0.10201901 | DV22: 0.09250642 | DW22: -0.081415413 | DX22: 0.17726337 | DY22: 0.23796029 | DZ22: 0.021146704 | EA22: -0.016671555 | EB22: -0.12393443 | EC22: -0.088085447 | ED22: 0.032747422 | EE22: 0.0016702628 | EF22: 0.034354893 | EG22: 0.11138979 | EH22: -0.0044865707 | EI22: 0.0098367297 | EJ22: 0.043268457 | EK22: 0.1079891 | EL22: 0.025307224 | EM22: =AVERAGE(C22:EL22) | EN22: =STDEV(C22:EL22) | EO22: =EM22/EN22
A23: 512 | B23: =ROUND($D$10/A23,0) | C23: 0.28298927 | D23: 0.025572739 | E23: 0.13300519 | F23: 0.0037402329 | G23: 0.36163212 | H23: -0.018188471 | I23: -0.036386489 | J23: 0.11487751 | K23: -0.059917885 | L23: -0.050770834 | M23: 0.14728697 | N23: 0.97590144 | O23: -0.12289971 | P23: -0.054681526 | Q23: -0.12030221 | R23: 0.062821978 | S23: 0.072572664 | T23: 0.084676176 | U23: -0.19395986 | V23: 0.086059987 | W23: 0.0041345118 | X23: 0.028624939 | Y23: -0.081246061 | Z23: -0.0015495125 | AA23: -0.10593172 | AB23: -0.1489752 | AC23: -0.17332009 | AD23: 0.042570963 | AE23: 0.027671992 | AF23: -0.17321352 | AG23: -0.05869778 | AH23: 0.03727949 | AI23: 0.1509141 | AJ23: 0.02358744 | AK23: -0.018557731 | AL23: 0.050760011 | AM23: -0.0073818797 | AN23: -0.037895355 | AO23: -0.032134598 | AP23: 0.16526637 | AQ23: 0.099380639 | AR23: 0.14613616 | AS23: 0.032167011 | AT23: -0.016951231 | AU23: 0.31867753 | AV23: 0.09675725 | AW23: 0.32642827 | AX23: 0.065137154 | AY23: 0.25265988 | AZ23: 0.078071577 | BA23: 0.053998339 | BB23: -0.56682653 | BC23: 0.1456179 | BD23: 0.065076817 | BE23: 0.17597478 | BF23: 0.050110962 | BG23: -0.023409412 | BH23: -0.053596864 | BI23: 0.12120552 | BJ23: -0.046193151 | BK23: -0.047849323 | BL23: -0.090236036 | BM23: 0.13895578 | BN23: -0.15467717 | BO23: 0.08042769 | BP23: -0.009863038 | BQ23: -0.17541276 | BR23: 0.0083521863 | BS23: 0.12567016 | BT23: 0.10807709 | BU23: 0.23163287 | BV23: -0.017018951 | BW23: 0.75172452 | BX23: -0.083160926 | BY23: 0.083991021 | BZ23: 0.35239787 | CA23: 0.17578985 | CB23: 0.05611433 | CC23: -0.084544615 | CD23: 0.11746832 | CE23: -0.014933939 | CF23: 0.077827622 | CG23: -0.50266725 | CH23: 0.021950564 | CI23: 0.059122474 | CJ23: -0.053625058 | CK23: -0.0015666454 | CL23: 0.34628583 | CM23: 0.019919502 | CN23: -0.020343066 | CO23: 0.16683225 | CP23: 0.030768384 | CQ23: 0.0078004512 | CR23: 0.0016288977 | CS23: 0.095512641 | CT23: 0.10388496 | CU23: 0.016525256 | CV23: 0.044376371 | CW23: 0.00072796851 | CX23: 0.053320206 | CY23: 0.019407873 | CZ23: 0.065292668 | DA23: 0.025018511 | DB23: 0.018747066 | DC23: 0.072416034 | DD23: 0.022498589 | DE23: 0.1414453 | DF23: 0.40879492 | DG23: 0.029625501 | DH23: 0.13922689 | DI23: 0.092924309 | DJ23: 0.057281999 | DK23: 0.063146578 | DL23: -0.014829391 | DM23: -0.033366756 | DN23: -0.04098991 | DO23: 0.12573219 | DP23: 0.060951312 | DQ23: 0.12113204 | DR23: -0.1024258 | DS23: -0.11657599 | DT23: -0.054250461 | DU23: 0.055639479 | DV23: -0.0081332536 | DW23: 0.023051821 | DX23: 0.3194491 | DY23: 0.20228413 | DZ23: 0.046410861 | EA23: -0.02875878 | EB23: -0.11582658 | EC23: -0.093644533 | ED23: -0.038900423 | EE23: 0.027630933 | EF23: 0.090054994 | EG23: 0.12590556 | EH23: -0.063317195 | EI23: 0.014102849 | EJ23: 0.038342925 | EK23: 0.12396271 | EL23: 0.049726084 | EM23: =AVERAGE(C23:EL23) | EN23: =STDEV(C23:EL23) | EO23: =EM23/EN23
A24: 1051 | B24: =ROUND($D$10/A24,0) | C24: 0.099113364 | D24: 0.10060991 | E24: 0.2845125 | F24: -0.075326494 | G24: 0.22960705 | H24: 0.035855797 | I24: 0.016927089 | J24: 0.1154628 | K24: 0.053732997 | L24: -0.093799693 | M24: 0.21778567 | N24: 1.7690314 | O24: -0.24427786 | P24: -0.0017362889 | Q24: -0.0028471356 | R24: -0.027822824 | S24: 0.01105446 | T24: 0.2878166 | U24: -0.28585629 | V24: 0.098678511 | W24: -0.16456452 | X24: -0.00089887647 | Y24: -0.12031749 | Z24: -0.024394549 | AA24: -0.094359583 | AB24: -0.18425142 | AC24: -0.24616896 | AD24: 0.1011753 | AE24: 0.17526882 | AF24: -0.16570378 | AG24: 0.10590047 | AH24: -0.068613799 | AI24: 0.31041424 | AJ24: 0.085435202 | AK24: -0.0014409771 | AL24: 0.087173701 | AM24: 0.078598498 | AN24: -0.16294174 | AO24: 0.082691716 | AP24: 0.16448669 | AQ24: 0.2171272 | AR24: 0.17083341 | AS24: 0.23783234 | AT24: -0.0059286096 | AU24: 0.47705419 | AV24: 0.019522214 | AW24: 0.12030292 | AX24: -0.025561798 | AY24: 0.44347344 | AZ24: 0.11862373 | BA24: 0.050491305 | BB24: -0.69077653 | BC24: 0.2057496 | BD24: 0.018631034 | BE24: 0.189489 | BF24: 0.08001195 | BG24: -0.17662354 | BH24: -0.009569451 | BI24: 0.16926892 | BJ24: -0.10732902 | BK24: -0.034827647 | BL24: -0.030898612 | BM24: -0.063550666 | BN24: 0.10891326 | BO24: -0.0056244216 | BP24: 0.031794104 | BQ24: -0.29185744 | BR24: -0.0096993971 | BS24: 0.038686934 | BT24: 0.27671902 | BU24: 0.0087484923 | BV24: -0.20330415 | BW24: 1.1090121 | BX24: -0.23222627 | BY24: 0.29033687 | BZ24: 0.81395803 | CA24: 0.33893068 | CB24: 0.052917307 | CC24: -0.18246988 | CD24: 0.018443351 | CE24: -0.055004727 | CF24: 0.16513135 | CG24: -0.23727783 | CH24: 0.14564333 | CI24: 0.058508157 | CJ24: -0.00125332 | CK24: -0.011405956 | CL24: 0.40508141 | CM24: 0.0027194555 | CN24: -0.054649002 | CO24: 0.08735443 | CP24: 0.038014899 | CQ24: 0.0443722 | CR24: 0.02212628 | CS24: 0.12151031 | CT24: 0.38294619 | CU24: -0.14645564 | CV24: 0.10310632 | CW24: -0.039824871 | CX24: -0.075681146 | CY24: 0.048689697 | CZ24: 0.13589801 | DA24: 0.033979585 | DB24: -0.016501866 | DC24: 0.17955312 | DD24: 0.002366865 | DE24: 0.22421824 | DF24: 0.52558501 | DG24: 0.11954529 | DH24: 0.26580268 | DI24: 0.14201474 | DJ24: 0.021081471 | DK24: 0.06348336 | DL24: 0.051807187 | DM24: 0.025807675 | DN24: 0.0053964329 | DO24: 0.15728782 | DP24: -0.018733008 | DQ24: 0.05048619 | DR24: -0.023391731 | DS24: -0.067362546 | DT24: -0.074733345 | DU24: -0.021781395 | DV24: -0.098046835 | DW24: 0.1011825 | DX24: 0.28592948 | DY24: -0.0032398766 | DZ24: -0.082108692 | EA24: -0.054920184 | EB24: -0.10922877 | EC24: -0.14364347 | ED24: 0.069835154 | EE24: 0.10748066 | EF24: 0.13408708 | EG24: 0.093659001 | EH24: 0.0011953681 | EI24: 0.11174428 | EJ24: -0.0067259821 | EK24: 0.13991261 | EL24: 0.25659149 | EM24: =AVERAGE(C24:EL24) | EN24: =STDEV(C24:EL24) | EO24: =EM24/EN24
A25: 大盤 | B25: TWII | C25: -0.017446771 | D25: 0.020701061 | E25: 0.023982129 | F25: -0.006557579 | G25: 0.03184513 | H25: 0.034348533 | I25: -0.0082549328 | J25: 0.012843524 | K25: -0.051018525 | L25: 0.00087394274 | M25: 0.023389576 | N25: 0.012988972 | O25: 0.0058545887 | P25: 0.027413207 | Q25: -0.0037129361 | R25: 0.024076614 | S25: -0.012190025 | T25: -0.039749578 | U25: -0.07315545 | V25: -0.05826023 | W25: 0.00077279757 | X25: 0.044591521 | Y25: -0.02769968 | Z25: 0.0020950059 | AA25: -0.023400551 | AB25: 0.032129371 | AC25: 0.038903273 | AD25: -0.042865382 | AE25: 0.018647195 | AF25: 0.015229768 | AG25: 0.036016604 | AH25: 0.0093546114 | AI25: 0.010748251 | AJ25: 0.013357754 | AK25: -0.0053327473 | AL25: 0.0013831358 | AM25: 0.020795928 | AN25: 0.031517702 | AO25: 0.0062417165 | AP25: 0.0061452617 | AQ25: 0.016946358 | AR25: 0.03468283 | AS25: 0.0030985886 | AT25: 0.015081347 | AU25: -0.019251209 | AV25: 0.038711513 | AW25: -0.021856951 | AX25: 0.0077743007 | AY25: 0.042397247 | AZ25: -0.026308975 | BA25: 0.0095717493 | BB25: -0.024249741 | BC25: 0.020163374 | BD25: -0.0035049988 | BE25: 0.020151935 | BF25: 0.00058133623 | BG25: -0.005219701 | BH25: -0.11587176 | BI25: 0.0087252257 | BJ25: -0.016377261 | BK25: 0.020840372 | BL25: 0.044975872 | BM25: 0.023954306 | BN25: 0.030239101 | BO25: -0.043725888 | BP25: 0.02188947 | BQ25: 0.0086274303 | BR25: -0.019192954 | BS25: 0.01973513 | BT25: 0.047694337 | BU25: 0.011454817 | BV25: 0.043228621 | BW25: -0.04274743 | BX25: -0.017811292 | BY25: -0.1511531 | BZ25: 0.124224 | CA25: -0.0045572538 | CB25: 0.06021124 | CC25: 0.085992033 | CD25: -0.0058084796 | CE25: -0.006041347 | CF25: 0.0024523244 | CG25: 0.089636252 | CH25: 0.070992733 | CI25: 0.027170643 | CJ25: 0.052468428 | CK25: 0.029480661 | CL25: 0.066825081 | CM25: -0.028772229 | CN25: 0.039462516 | CO25: -0.029031087 | CP25: 0.013983883 | CQ25: -0.032276965 | CR25: 0.0031035766 | CS25: 0.025591856 | CT25: 0.044391886 | CU25: -0.030338959 | CV25: -0.0012579765 | CW25: 0.0023363565 | CX25: -0.064264145 | CY25: 0.012909779 | CZ25: -0.12547709 | DA25: 0.011690683 | DB25: 0.0063378437 | DC25: -0.11730536 | DD25: -0.036010872 | DE25: 0.1389113 | DF25: -0.051143506 | DG25: 0.076731447 | DH25: 0.015508782 | DI25: 0.023223774 | DJ25: -0.018372876 | DK25: 0.062199014 | DL25: 0.020098304 | DM25: 0.01349894 | DN25: -0.030252213 | DO25: -0.017022836 | DP25: -0.021788523 | DQ25: 0.085745625 | DR25: 0.028106744 | DS25: -0.0023031598 | DT25: 0.058471198 | DU25: 0.067658949 | DV25: 0.0050207706 | DW25: 0.037416184 | DX25: 0.084111004 | DY25: -0.036832399 | DZ25: 0.0030917028 | EA25: -0.0019576282 | EB25: 0.026459104 | EC25: -0.024752539 | ED25: 0.034115491 | EE25: 0.021061974 | EF25: -0.020277393 | EG25: -0.10786811 | EH25: -0.022520352 | EI25: 0.053510007 | EJ25: 0.041687266 | EK25: 0.056195614 | EL25: 0.028911319 | EM25: =AVERAGE(C25:EL25) | EN25: =STDEV(C25:EL25) | EO25: =EM25/EN25

Sheet 勝率
A1: Real
B2: Time | C2: 2013/12 | D2: 2014/01 | E2: 2014/02 | F2: 2014/03 | G2: 2014/04 | H2: 2014/05 | I2: 2014/06 | J2: 2014/07 | K2: 2014/08 | L2: 2014/09 | M2: 2014/10 | N2: 2014/11 | O2: 2014/12 | P2: 2015/01 | Q2: 2015/02 | R2: 2015/03 | S2: 2015/04 | T2: 2015/05 | U2: 2015/06 | V2: 2015/07 | W2: 2015/08 | X2: 2015/09 | Y2: 2015/10 | Z2: 2015/11 | AA2: 2015/12 | AB2: 2016/01 | AC2: 2016/02 | AD2: 2016/03 | AE2: 2016/04 | AF2: 2016/05 | AG2: 2016/06 | AH2: 2016/07 | AI2: 2016/08 | AJ2: 2016/09 | AK2: 2016/10 | AL2: 2016/11 | AM2: 2016/12 | AN2: 2017/01 | AO2: 2017/02 | AP2: 2017/03 | AQ2: 2017/04 | AR2: 2017/05 | AS2: 2017/06 | AT2: 2017/07 | AU2: 2017/08 | AV2: 2017/09 | AW2: 2017/10 | AX2: 2017/11 | AY2: 2017/12 | AZ2: 2018/01 | BA2: 2018/02 | BB2: 2018/03 | BC2: 2018/04 | BD2: 2018/05 | BE2: 2018/06 | BF2: 2018/07 | BG2: 2018/08 | BH2: 2018/09 | BI2: 2018/10 | BJ2: 2018/11 | BK2: 2018/12 | BL2: 2019/01 | BM2: 2019/02 | BN2: 2019/03 | BO2: 2019/04 | BP2: 2019/05 | BQ2: 2019/06 | BR2: 2019/07 | BS2: 2019/08 | BT2: 2019/09 | BU2: 2019/10 | BV2: 2019/11 | BW2: 2019/12 | BX2: 2020/01 | BY2: 2020/02 | BZ2: 2020/03 | CA2: 2020/04 | CB2: 2020/05 | CC2: 2020/06 | CD2: 2020/07 | CE2: 2020/08 | CF2: 2020/09 | CG2: 2020/10 | CH2: 2020/11 | CI2: 2020/12 | CJ2: 2021/01 | CK2: 2021/02 | CL2: 2021/03 | CM2: 2021/04 | CN2: 2021/05 | CO2: 2021/06 | CP2: 2021/07 | CQ2: 2021/08 | CR2: 2021/09 | CS2: 2021/10 | CT2: 2021/11 | CU2: 2021/12 | CV2: 2022/01 | CW2: 2022/02 | CX2: 2022/03 | CY2: 2022/04 | CZ2: 2022/05 | DA2: 2022/06 | DB2: 2022/07 | DC2: 2022/08 | DD2: 2022/09 | DE2: 2022/10 | DF2: 2022/11 | DG2: 2022/12 | DH2: 2023/01 | DI2: 2023/02 | DJ2: 2023/03 | DK2: 2023/04 | DL2: 2023/05 | DM2: 2023/06 | DN2: 2023/07 | DO2: 2023/08 | DP2: 2023/09 | DQ2: 2023/10 | DR2: 2023/11 | DS2: 2023/12 | DT2: 2024/01 | DU2: 2024/02 | DV2: 2024/03 | DW2: 2024/04 | DX2: 2024/05 | DY2: 2024/06 | DZ2: 2024/07 | EA2: 2024/08 | EB2: 2024/09 | EC2: 2024/10 | ED2: 2024/11 | EE2: 2024/12 | EF2: 2025/01 | EG2: 2025/02 | EH2: 2025/03 | EI2: 2025/04 | EJ2: 2025/05 | EK2: 2025/06 | EL2: 2025/07 | EM2: 2025/08
B3: bm | C3: 0.11254353 | D3: 0.034097093 | E3: -0.034092261 | F3: -0.016058652 | G3: -0.0032385096 | H3: 0.037901102 | I3: 0.19658042 | J3: 0.123748 | K3: -0.0034480581 | L3: 0.056295168 | M3: -0.033270601 | N3: 0.13532466 | O3: 0.02969531 | P3: -0.075919536 | Q3: -0.062747606 | R3: 0.034334773 | S3: -0.11448918 | T3: -0.128411 | U3: -0.01815403 | V3: 0.097284226 | W3: 0.06448606 | X3: 0.1327038 | Y3: -0.14506291 | Z3: 0.15983802 | AA3: -0.079439674 | AB3: 0.065463771 | AC3: 0.10841757 | AD3: 0.035162094 | AE3: -0.13259397 | AF3: 0.079167282 | AG3: 0.1474472 | AH3: 0.10818108 | AI3: 0.031505046 | AJ3: 0.068324574 | AK3: 0.13938042 | AL3: 0.0015927447 | AM3: 0.11699323 | AN3: 0.18348806 | AO3: -0.013624633 | AP3: -0.10636754 | AQ3: -0.026929215 | AR3: 0.042036531 | AS3: 0.018696587 | AT3: 0.050640506 | AU3: 0.060413159 | AV3: -0.049074617 | AW3: 0.041357509 | AX3: 0.1327231 | AY3: 0.05462578 | AZ3: 0.015696796 | BA3: 0.012690345 | BB3: 0.10435302 | BC3: 0.027796633 | BD3: 0.015784322 | BE3: 0.053739938 | BF3: 0.15375844 | BG3: 0.14726982 | BH3: 0.058771535 | BI3: 0.089685564 | BJ3: -0.041235808 | BK3: -0.085734728 | BL3: 0.06541404 | BM3: -0.031368353 | BN3: 0.035359622 | BO3: 0.077704285 | BP3: -0.014539108 | BQ3: 0.054478665 | BR3: -0.011979953 | BS3: 0.061686425 | BT3: 0.017609737 | BU3: 0.001762998 | BV3: 0.079901428 | BW3: -0.026106377 | BX3: 0.022152374 | BY3: -0.070677725 | BZ3: 0.10127162 | CA3: -0.11166328 | CB3: 0.021342222 | CC3: -0.0047361279 | CD3: 0.17955101 | CE3: 0.061307643 | CF3: 0.091604774 | CG3: 0.097692005 | CH3: 0.15714712 | CI3: -0.088647186 | CJ3: -0.014935576 | CK3: 0.038208336 | CL3: 0.31725854 | CM3: -0.04994997 | CN3: -0.038447027 | CO3: 0.00071081192 | CP3: 0.14471258 | CQ3: 0.14928899 | CR3: -0.039801054 | CS3: -0.046545919 | CT3: 0.034133664 | CU3: 0.12875406 | CV3: 0.031635368 | CW3: 0.041194563 | CX3: 0.16319544 | CY3: -0.043115028 | CZ3: 0.22006844 | DA3: -0.04142373 | DB3: -0.011737974 | DC3: 0.10777107 | DD3: 0.067224014 | DE3: -0.040137128 | DF3: 0.036396903 | DG3: -0.098061051 | DH3: -0.012045848 | DI3: -0.089410575 | DJ3: 0.054992879 | DK3: -0.057186589 | DL3: -0.029284301 | DM3: -0.031402929 | DN3: 0.084413623 | DO3: 0.048170818 | DP3: 0.090346423 | DQ3: -0.11867639 | DR3: 0.11050757 | DS3: -0.073814619 | DT3: -0.10633883 | DU3: 0.0096230219 | DV3: 0.14417122 | DW3: 0.085312212 | DX3: -0.11038018 | DY3: 0.12870772 | DZ3: -0.053270106 | EA3: 0.17325686 | EB3: 0.012264442 | EC3: 0.077320493 | ED3: -0.16510374 | EE3: 0.077592443 | EF3: 0.056688315 | EG3: 0.1757144 | EH3: -0.050736759 | EI3: -0.032979675 | EJ3: -0.1750733 | EK3: 0.075703333 | EL3: -0.11145874 | EM3: #NUM!
